Workbook

Sheet Takip Tablosu
A1: Sırala: | B1: Haftalık Sıra | C1: ◀ seçince tablo o sıraya göre dizilir
A3: Fon Kodu | B3: Günlük Sıra | C3: Haftalık Sıra | D3: Aylık Sıra | E3: Yılbaşına Göre | F3: Yıllık Sıra | G3: Kat. Toplam | H3: Kategori
A4: =INDEX(VeriTakip!A$2:A$15,MATCH(SMALL(VeriTakip!$J$2:$J$15,ROW()-3),VeriTakip!$J$2:$J$15,0)) -> BIS | B4: =INDEX(VeriTakip!B$2:B$15,MATCH(SMALL(VeriTakip!$J$2:$J$15,ROW()-3),VeriTakip!$J$2:$J$15,0)) -> 27 | C4: =INDEX(VeriTakip!C$2:C$15,MATCH(SMALL(VeriTakip!$J$2:$J$15,ROW()-3),VeriTakip!$J$2:$J$15,0)) -> 1 | D4: =INDEX(VeriTakip!D$2:D$15,MATCH(SMALL(VeriTakip!$J$2:$J$15,ROW()-3),VeriTakip!$J$2:$J$15,0)) -> 2 | E4: =INDEX(VeriTakip!E$2:E$15,MATCH(SMALL(VeriTakip!$J$2:$J$15,ROW()-3),VeriTakip!$J$2:$J$15,0)) -> 1 | F4: =INDEX(VeriTakip!F$2:F$15,MATCH(SMALL(VeriTakip!$J$2:$J$15,ROW()-3),VeriTakip!$J$2:$J$15,0)) -> 2 | G4: =INDEX(VeriTakip!G$2:G$15,MATCH(SMALL(VeriTakip!$J$2:$J$15,ROW()-3),VeriTakip!$J$2:$J$15,0)) -> 27 | H4: =INDEX(VeriTakip!H$2:H$15,MATCH(SMALL(VeriTakip!$J$2:$J$15,ROW()-3),VeriTakip!$J$2:$J$15,0)) -> Döviz
A5: =INDEX(VeriTakip!A$2:A$15,MATCH(SMALL(VeriTakip!$J$2:$J$15,ROW()-3),VeriTakip!$J$2:$J$15,0)) -> SPR | B5: =INDEX(VeriTakip!B$2:B$15,MATCH(SMALL(VeriTakip!$J$2:$J$15,ROW()-3),VeriTakip!$J$2:$J$15,0)) -> 1 | C5: =INDEX(VeriTakip!C$2:C$15,MATCH(SMALL(VeriTakip!$J$2:$J$15,ROW()-3),VeriTakip!$J$2:$J$15,0)) -> 1 | D5: =INDEX(VeriTakip!D$2:D$15,MATCH(SMALL(VeriTakip!$J$2:$J$15,ROW()-3),VeriTakip!$J$2:$J$15,0)) -> 10 | E5: =INDEX(VeriTakip!E$2:E$15,MATCH(SMALL(VeriTakip!$J$2:$J$15,ROW()-3),VeriTakip!$J$2:$J$15,0)) -> 57 | F5: =INDEX(VeriTakip!F$2:F$15,MATCH(SMALL(VeriTakip!$J$2:$J$15,ROW()-3),VeriTakip!$J$2:$J$15,0)) -> 55 | G5: =INDEX(VeriTakip!G$2:G$15,MATCH(SMALL(VeriTakip!$J$2:$J$15,ROW()-3),VeriTakip!$J$2:$J$15,0)) -> 58 | H5: =INDEX(VeriTakip!H$2:H$15,MATCH(SMALL(VeriTakip!$J$2:$J$15,ROW()-3),VeriTakip!$J$2:$J$15,0)) -> Tüm Teknoloji
A6: =INDEX(VeriTakip!A$2:A$15,MATCH(SMALL(VeriTakip!$J$2:$J$15,ROW()-3),VeriTakip!$J$2:$J$15,0)) -> BVZ | B6: =INDEX(VeriTakip!B$2:B$15,MATCH(SMALL(VeriTakip!$J$2:$J$15,ROW()-3),VeriTakip!$J$2:$J$15,0)) -> 5 | C6: =INDEX(VeriTakip!C$2:C$15,MATCH(SMALL(VeriTakip!$J$2:$J$15,ROW()-3),VeriTakip!$J$2:$J$15,0)) -> 2 | D6: =INDEX(VeriTakip!D$2:D$15,MATCH(SMALL(VeriTakip!$J$2:$J$15,ROW()-3),VeriTakip!$J$2:$J$15,0)) -> 4 | E6: =INDEX(VeriTakip!E$2:E$15,MATCH(SMALL(VeriTakip!$J$2:$J$15,ROW()-3),VeriTakip!$J$2:$J$15,0)) -> 4 | F6: =INDEX(VeriTakip!F$2:F$15,MATCH(SMALL(VeriTakip!$J$2:$J$15,ROW()-3),VeriTakip!$J$2:$J$15,0)) -> 5 | G6: =INDEX(VeriTakip!G$2:G$15,MATCH(SMALL(VeriTakip!$J$2:$J$15,ROW()-3),VeriTakip!$J$2:$J$15,0)) -> 13 | H6: =INDEX(VeriTakip!H$2:H$15,MATCH(SMALL(VeriTakip!$J$2:$J$15,ROW()-3),VeriTakip!$J$2:$J$15,0)) -> Arbitraj
A7: =INDEX(VeriTakip!A$2:A$15,MATCH(SMALL(VeriTakip!$J$2:$J$15,ROW()-3),VeriTakip!$J$2:$J$15,0)) -> BTE | B7: =INDEX(VeriTakip!B$2:B$15,MATCH(SMALL(VeriTakip!$J$2:$J$15,ROW()-3),VeriTakip!$J$2:$J$15,0)) -> 2 | C7: =INDEX(VeriTakip!C$2:C$15,MATCH(SMALL(VeriTakip!$J$2:$J$15,ROW()-3),VeriTakip!$J$2:$J$15,0)) -> 2 | D7: =INDEX(VeriTakip!D$2:D$15,MATCH(SMALL(VeriTakip!$J$2:$J$15,ROW()-3),VeriTakip!$J$2:$J$15,0)) -> 1 | E7: =INDEX(VeriTakip!E$2:E$15,MATCH(SMALL(VeriTakip!$J$2:$J$15,ROW()-3),VeriTakip!$J$2:$J$15,0)) -> 1 | F7: =INDEX(VeriTakip!F$2:F$15,MATCH(SMALL(VeriTakip!$J$2:$J$15,ROW()-3),VeriTakip!$J$2:$J$15,0)) -> 1 | G7: =INDEX(VeriTakip!G$2:G$15,MATCH(SMALL(VeriTakip!$J$2:$J$15,ROW()-3),VeriTakip!$J$2:$J$15,0)) -> 2 | H7: =INDEX(VeriTakip!H$2:H$15,MATCH(SMALL(VeriTakip!$J$2:$J$15,ROW()-3),VeriTakip!$J$2:$J$15,0)) -> Oyun
A8: =INDEX(VeriTakip!A$2:A$15,MATCH(SMALL(VeriTakip!$J$2:$J$15,ROW()-3),VeriTakip!$J$2:$J$15,0)) -> BSD | B8: =INDEX(VeriTakip!B$2:B$15,MATCH(SMALL(VeriTakip!$J$2:$J$15,ROW()-3),VeriTakip!$J$2:$J$15,0)) -> 25 | C8: =INDEX(VeriTakip!C$2:C$15,MATCH(SMALL(VeriTakip!$J$2:$J$15,ROW()-3),VeriTakip!$J$2:$J$15,0)) -> 3 | D8: =INDEX(VeriTakip!D$2:D$15,MATCH(SMALL(VeriTakip!$J$2:$J$15,ROW()-3),VeriTakip!$J$2:$J$15,0)) -> 4 | E8: =INDEX(VeriTakip!E$2:E$15,MATCH(SMALL(VeriTakip!$J$2:$J$15,ROW()-3),VeriTakip!$J$2:$J$15,0)) -> 3 | F8: =INDEX(VeriTakip!F$2:F$15,MATCH(SMALL(VeriTakip!$J$2:$J$15,ROW()-3),VeriTakip!$J$2:$J$15,0)) -> - | G8: =INDEX(VeriTakip!G$2:G$15,MATCH(SMALL(VeriTakip!$J$2:$J$15,ROW()-3),VeriTakip!$J$2:$J$15,0)) -> 27 | H8: =INDEX(VeriTakip!H$2:H$15,MATCH(SMALL(VeriTakip!$J$2:$J$15,ROW()-3),VeriTakip!$J$2:$J$15,0)) -> Döviz
A9: =INDEX(VeriTakip!A$2:A$15,MATCH(SMALL(VeriTakip!$J$2:$J$15,ROW()-3),VeriTakip!$J$2:$J$15,0)) -> BVD | B9: =INDEX(VeriTakip!B$2:B$15,MATCH(SMALL(VeriTakip!$J$2:$J$15,ROW()-3),VeriTakip!$J$2:$J$15,0)) -> 8 | C9: =INDEX(VeriTakip!C$2:C$15,MATCH(SMALL(VeriTakip!$J$2:$J$15,ROW()-3),VeriTakip!$J$2:$J$15,0)) -> 3 | D9: =INDEX(VeriTakip!D$2:D$15,MATCH(SMALL(VeriTakip!$J$2:$J$15,ROW()-3),VeriTakip!$J$2:$J$15,0)) -> 6 | E9: =INDEX(VeriTakip!E$2:E$15,MATCH(SMALL(VeriTakip!$J$2:$J$15,ROW()-3),VeriTakip!$J$2:$J$15,0)) -> 1 | F9: =INDEX(VeriTakip!F$2:F$15,MATCH(SMALL(VeriTakip!$J$2:$J$15,ROW()-3),VeriTakip!$J$2:$J$15,0)) -> - | G9: =INDEX(VeriTakip!G$2:G$15,MATCH(SMALL(VeriTakip!$J$2:$J$15,ROW()-3),VeriTakip!$J$2:$J$15,0)) -> 28 | H9: =INDEX(VeriTakip!H$2:H$15,MATCH(SMALL(VeriTakip!$J$2:$J$15,ROW()-3),VeriTakip!$J$2:$J$15,0)) -> Dengeli Değişken
A10: =INDEX(VeriTakip!A$2:A$15,MATCH(SMALL(VeriTakip!$J$2:$J$15,ROW()-3),VeriTakip!$J$2:$J$15,0)) -> BHI | B10: =INDEX(VeriTakip!B$2:B$15,MATCH(SMALL(VeriTakip!$J$2:$J$15,ROW()-3),VeriTakip!$J$2:$J$15,0)) -> 7 | C10: =INDEX(VeriTakip!C$2:C$15,MATCH(SMALL(VeriTakip!$J$2:$J$15,ROW()-3),VeriTakip!$J$2:$J$15,0)) -> 7 | D10: =INDEX(VeriTakip!D$2:D$15,MATCH(SMALL(VeriTakip!$J$2:$J$15,ROW()-3),VeriTakip!$J$2:$J$15,0)) -> 3 | E10: =INDEX(VeriTakip!E$2:E$15,MATCH(SMALL(VeriTakip!$J$2:$J$15,ROW()-3),VeriTakip!$J$2:$J$15,0)) -> 1 | F10: =INDEX(VeriTakip!F$2:F$15,MATCH(SMALL(VeriTakip!$J$2:$J$15,ROW()-3),VeriTakip!$J$2:$J$15,0)) -> 1 | G10: =INDEX(VeriTakip!G$2:G$15,MATCH(SMALL(VeriTakip!$J$2:$J$15,ROW()-3),VeriTakip!$J$2:$J$15,0)) -> 24 | H10: =INDEX(VeriTakip!H$2:H$15,MATCH(SMALL(VeriTakip!$J$2:$J$15,ROW()-3),VeriTakip!$J$2:$J$15,0)) -> Mutlak Getiri
A11: =INDEX(VeriTakip!A$2:A$15,MATCH(SMALL(VeriTakip!$J$2:$J$15,ROW()-3),VeriTakip!$J$2:$J$15,0)) -> BVF | B11: =INDEX(VeriTakip!B$2:B$15,MATCH(SMALL(VeriTakip!$J$2:$J$15,ROW()-3),VeriTakip!$J$2:$J$15,0)) -> 10 | C11: =INDEX(VeriTakip!C$2:C$15,MATCH(SMALL(VeriTakip!$J$2:$J$15,ROW()-3),VeriTakip!$J$2:$J$15,0)) -> 7 | D11: =INDEX(VeriTakip!D$2:D$15,MATCH(SMALL(VeriTakip!$J$2:$J$15,ROW()-3),VeriTakip!$J$2:$J$15,0)) -> 10 | E11: =INDEX(VeriTakip!E$2:E$15,MATCH(SMALL(VeriTakip!$J$2:$J$15,ROW()-3),VeriTakip!$J$2:$J$15,0)) -> 7 | F11: =INDEX(VeriTakip!F$2:F$15,MATCH(SMALL(VeriTakip!$J$2:$J$15,ROW()-3),VeriTakip!$J$2:$J$15,0)) -> - | G11: =INDEX(VeriTakip!G$2:G$15,MATCH(SMALL(VeriTakip!$J$2:$J$15,ROW()-3),VeriTakip!$J$2:$J$15,0)) -> 61 | H11: =INDEX(VeriTakip!H$2:H$15,MATCH(SMALL(VeriTakip!$J$2:$J$15,ROW()-3),VeriTakip!$J$2:$J$15,0)) -> Para Piyasası
A12: =INDEX(VeriTakip!A$2:A$15,MATCH(SMALL(VeriTakip!$J$2:$J$15,ROW()-3),VeriTakip!$J$2:$J$15,0)) -> RUT | B12: =INDEX(VeriTakip!B$2:B$15,MATCH(SMALL(VeriTakip!$J$2:$J$15,ROW()-3),VeriTakip!$J$2:$J$15,0)) -> 8 | C12: =INDEX(VeriTakip!C$2:C$15,MATCH(SMALL(VeriTakip!$J$2:$J$15,ROW()-3),VeriTakip!$J$2:$J$15,0)) -> 7 | D12: =INDEX(VeriTakip!D$2:D$15,MATCH(SMALL(VeriTakip!$J$2:$J$15,ROW()-3),VeriTakip!$J$2:$J$15,0)) -> 6 | E12: =INDEX(VeriTakip!E$2:E$15,MATCH(SMALL(VeriTakip!$J$2:$J$15,ROW()-3),VeriTakip!$J$2:$J$15,0)) -> 4 | F12: =INDEX(VeriTakip!F$2:F$15,MATCH(SMALL(VeriTakip!$J$2:$J$15,ROW()-3),VeriTakip!$J$2:$J$15,0)) -> 4 | G12: =INDEX(VeriTakip!G$2:G$15,MATCH(SMALL(VeriTakip!$J$2:$J$15,ROW()-3),VeriTakip!$J$2:$J$15,0)) -> 9 | H12: =INDEX(VeriTakip!H$2:H$15,MATCH(SMALL(VeriTakip!$J$2:$J$15,ROW()-3),VeriTakip!$J$2:$J$15,0)) -> RUT
A13: =INDEX(VeriTakip!A$2:A$15,MATCH(SMALL(VeriTakip!$J$2:$J$15,ROW()-3),VeriTakip!$J$2:$J$15,0)) -> BV1 | B13: =INDEX(VeriTakip!B$2:B$15,MATCH(SMALL(VeriTakip!$J$2:$J$15,ROW()-3),VeriTakip!$J$2:$J$15,0)) -> 23 | C13: =INDEX(VeriTakip!C$2:C$15,MATCH(SMALL(VeriTakip!$J$2:$J$15,ROW()-3),VeriTakip!$J$2:$J$15,0)) -> 8 | D13: =INDEX(VeriTakip!D$2:D$15,MATCH(SMALL(VeriTakip!$J$2:$J$15,ROW()-3),VeriTakip!$J$2:$J$15,0)) -> 11 | E13: =INDEX(VeriTakip!E$2:E$15,MATCH(SMALL(VeriTakip!$J$2:$J$15,ROW()-3),VeriTakip!$J$2:$J$15,0)) -> 19 | F13: =INDEX(VeriTakip!F$2:F$15,MATCH(SMALL(VeriTakip!$J$2:$J$15,ROW()-3),VeriTakip!$J$2:$J$15,0)) -> 7 | G13: =INDEX(VeriTakip!G$2:G$15,MATCH(SMALL(VeriTakip!$J$2:$J$15,ROW()-3),VeriTakip!$J$2:$J$15,0)) -> 41 | H13: =INDEX(VeriTakip!H$2:H$15,MATCH(SMALL(VeriTakip!$J$2:$J$15,ROW()-3),VeriTakip!$J$2:$J$15,0)) -> Hisse
A14: =INDEX(VeriTakip!A$2:A$15,MATCH(SMALL(VeriTakip!$J$2:$J$15,ROW()-3),VeriTakip!$J$2:$J$15,0)) -> MTD | B14: =INDEX(VeriTakip!B$2:B$15,MATCH(SMALL(VeriTakip!$J$2:$J$15,ROW()-3),VeriTakip!$J$2:$J$15,0)) -> 12 | C14: =INDEX(VeriTakip!C$2:C$15,MATCH(SMALL(VeriTakip!$J$2:$J$15,ROW()-3),VeriTakip!$J$2:$J$15,0)) -> 12 | D14: =INDEX(VeriTakip!D$2:D$15,MATCH(SMALL(VeriTakip!$J$2:$J$15,ROW()-3),VeriTakip!$J$2:$J$15,0)) -> 17 | E14: =INDEX(VeriTakip!E$2:E$15,MATCH(SMALL(VeriTakip!$J$2:$J$15,ROW()-3),VeriTakip!$J$2:$J$15,0)) -> 17 | F14: =INDEX(VeriTakip!F$2:F$15,MATCH(SMALL(VeriTakip!$J$2:$J$15,ROW()-3),VeriTakip!$J$2:$J$15,0)) -> - | G14: =INDEX(VeriTakip!G$2:G$15,MATCH(SMALL(VeriTakip!$J$2:$J$15,ROW()-3),VeriTakip!$J$2:$J$15,0)) -> 18 | H14: =INDEX(VeriTakip!H$2:H$15,MATCH(SMALL(VeriTakip!$J$2:$J$15,ROW()-3),VeriTakip!$J$2:$J$15,0)) -> Teknoloji
A15: =INDEX(VeriTakip!A$2:A$15,MATCH(SMALL(VeriTakip!$J$2:$J$15,ROW()-3),VeriTakip!$J$2:$J$15,0)) -> BVV | B15: =INDEX(VeriTakip!B$2:B$15,MATCH(SMALL(VeriTakip!$J$2:$J$15,ROW()-3),VeriTakip!$J$2:$J$15,0)) -> 14 | C15: =INDEX(VeriTakip!C$2:C$15,MATCH(SMALL(VeriTakip!$J$2:$J$15,ROW()-3),VeriTakip!$J$2:$J$15,0)) -> 14 | D15: =INDEX(VeriTakip!D$2:D$15,MATCH(SMALL(VeriTakip!$J$2:$J$15,ROW()-3),VeriTakip!$J$2:$J$15,0)) -> 8 | E15: =INDEX(VeriTakip!E$2:E$15,MATCH(SMALL(VeriTakip!$J$2:$J$15,ROW()-3),VeriTakip!$J$2:$J$15,0)) -> 3 | F15: =INDEX(VeriTakip!F$2:F$15,MATCH(SMALL(VeriTakip!$J$2:$J$15,ROW()-3),VeriTakip!$J$2:$J$15,0)) -> 2 | G15: =INDEX(VeriTakip!G$2:G$15,MATCH(SMALL(VeriTakip!$J$2:$J$15,ROW()-3),VeriTakip!$J$2:$J$15,0)) -> 18 | H15: =INDEX(VeriTakip!H$2:H$15,MATCH(SMALL(VeriTakip!$J$2:$J$15,ROW()-3),VeriTakip!$J$2:$J$15,0)) -> Teknoloji
... A17: =INDEX(VeriTakip!A$2:A$15,MATCH(SMALL(VeriTakip!$J$2:$J$15,ROW()-3),VeriTakip!$J$2:$J$15,0)) -> BAI | B17: =INDEX(VeriTakip!B$2:B$15,MATCH(SMALL(VeriTakip!$J$2:$J$15,ROW()-3),VeriTakip!$J$2:$J$15,0)) -> 35 | C17: =INDEX(VeriTakip!C$2:C$15,MATCH(SMALL(VeriTakip!$J$2:$J$15,ROW()-3),VeriTakip!$J$2:$J$15,0)) -> - | D17: =INDEX(VeriTakip!D$2:D$15,MATCH(SMALL(VeriTakip!$J$2:$J$15,ROW()-3),VeriTakip!$J$2:$J$15,0)) -> - | E17: =INDEX(VeriTakip!E$2:E$15,MATCH(SMALL(VeriTakip!$J$2:$J$15,ROW()-3),VeriTakip!$J$2:$J$15,0)) -> - | F17: =INDEX(VeriTakip!F$2:F$15,MATCH(SMALL(VeriTakip!$J$2:$J$15,ROW()-3),VeriTakip!$J$2:$J$15,0)) -> - | G17: =INDEX(VeriTakip!G$2:G$15,MATCH(SMALL(VeriTakip!$J$2:$J$15,ROW()-3),VeriTakip!$J$2:$J$15,0)) -> 47 | H17: =INDEX(VeriTakip!H$2:H$15,MATCH(SMALL(VeriTakip!$J$2:$J$15,ROW()-3),VeriTakip!$J$2:$J$15,0)) -> Altın

Sheet V_Arbitraj
A1: Fon Kodu | B1: Arbitraj Fonları | C1: Yönetici | D1: FYÜ% | E1: Günlük% | F1: Haftalık | G1: Aylık | H1: Yılbaşına Göre | I1: Yıllık | J1: Yatırımcı Sayısı T-30 | K1: Yatırımcı Sayısı T-1 | L1: YS Değişim | M1: Önceki Ay FTD | N1: T-1 FTD | O1: FTD Değişim | P1: Standart Sapma (Aylık) | Q1: TEFAS Durumu | R1: Mevduat (TL) | S1: Vadeli İşlemler Nakit Teminatları | T1: Ters Repo Oranı | U1: Hisse Oranı | V1: Para Piyasaları Oranı | W1: Yatırım Fonları Katılma Payları | X1: Özel Tahvil/Bono Oranı | Y1: Finansman Bonosu Oranı | Z1: Diğer Oran | AA1: Toplam
A2: ICN | B2: İstanbul Portföy Üçüncü İstatistiksel Arbitraj Serbest (TL) Fon | C2: İstanbul Portföy | D2: 0.0315 | E2: 0.47122477 | F2: 0.81708437 | G2: 3.2703729 | H2: 25.837835 | I2: 52.90876 | J2: 15 | K2: 14 | L2: -0.066666667 | M2: 1.6550216e+08 | N2: 1.7048085e+08 | O2: 0.030082354 | P2: 0.14980409 | Q2: Görmüyor | R2: 0 | S2: 0.2963 | T2: 0 | U2: 0 | V2: 0 | W2: 0.7031 | X2: 0 | Y2: 0 | Z2: 0 | AA2: 0.9994 | AC2: =IF(ISNUMBER(INDEX($A$2:$AA$14,1,MATCH(Arbitraj!$E$2,$A$1:$AA$1,0))),INDEX($A$2:$AA$14,1,MATCH(Arbitraj!$E$2,$A$1:$AA$1,0)),-1000000000)-ROW()/10000000 -> 0.47122457
A3: IRV | B3: İstanbul Portföy İstatistiksel Arbitraj Serbest Fon | C3: İstanbul Portföy | D3: 0.03 | E3: 0.29038708 | F3: 0.61558927 | G3: 3.87085 | H3: 18.470973 | I3: 38.288144 | J3: 35 | K3: 36 | L3: 0.028571429 | M3: 2.5227015e+08 | N3: 2.8645493e+08 | O3: 0.13550865 | P3: 0.19501499 | Q3: Görüyor | R3: 0 | S3: 0.1788 | T3: 0 | U3: 0.6072 | V3: 0 | W3: 0.139 | X3: 0 | Y3: 0.0767 | Z3: -0.0021 | AA3: 0.9996 | AC3: =IF(ISNUMBER(INDEX($A$2:$AA$14,2,MATCH(Arbitraj!$E$2,$A$1:$AA$1,0))),INDEX($A$2:$AA$14,2,MATCH(Arbitraj!$E$2,$A$1:$AA$1,0)),-1000000000)-ROW()/10000000 -> 0.29038678
A4: LPH | B4: Statech Portföy İstatistiksel Arbitraj Hisse Senedi Serbest (TL) Fon (Hisse Senedi Yoğun Fon) | C4: Statech Portföy | D4: 0.035 | E4: 0.28554763 | F4: 0.95667656 | G4: 3.4575854 | H4: 31.611835 | I4: 64.932363 | J4: 1661 | K4: 1683 | L4: 0.013245033 | M4: 1.6244287e+09 | N4: 2.2403628e+09 | O4: 0.37916968 | P4: 0.13407652 | Q4: Görüyor | R4: 0 | S4: 0.1463 | T4: 0 | U4: 0.8537 | V4: 0 | W4: 0 | X4: 0 | Y4: 0 | Z4: 0 | AA4: 1 | AC4: =IF(ISNUMBER(INDEX($A$2:$AA$14,3,MATCH(Arbitraj!$E$2,$A$1:$AA$1,0))),INDEX($A$2:$AA$14,3,MATCH(Arbitraj!$E$2,$A$1:$AA$1,0)),-1000000000)-ROW()/10000000 -> 0.28554723
A5: TCI | B5: Tacirler Portföy İstatistiksel Arbitraj Serbest Fon | C5: Tacirler Portföy | D5: 0.035 | E5: 0.26090605 | F5: 0.70593745 | G5: 3.2436742 | H5: 21.828324 | I5: 44.311736 | J5: 17 | K5: 16 | L5: -0.058823529 | M5: 1.3856132e+09 | N5: 1.3525342e+09 | O5: -0.023873217 | P5: 0.086020675 | Q5: Görmüyor | R5: 0.1544 | S5: 0.074 | T5: 0.3305 | U5: 0.1209 | V5: 0.0004 | W5: 0.186 | X5: 0 | Y5: 0.1338 | Z5: 0 | AA5: 1 | AC5: =IF(ISNUMBER(INDEX($A$2:$AA$14,4,MATCH(Arbitraj!$E$2,$A$1:$AA$1,0))),INDEX($A$2:$AA$14,4,MATCH(Arbitraj!$E$2,$A$1:$AA$1,0)),-1000000000)-ROW()/10000000 -> 0.26090555
A6: BVZ | B6: BV Portföy İstatistiksel Arbitraj Serbest (TL) Fon | C6: BV Portföy | D6: 0.042 | E6: 0.24709811 | F6: 0.86947754 | G6: 3.5748564 | H6: 23.814921 | I6: 47.823586 | J6: 704 | K6: 678 | L6: -0.036931818 | M6: 2.9530498e+09 | N6: 2.6975042e+09 | O6: -0.08653615 | P6: 0.083391418 | Q6: Görüyor | R6: 0 | S6: 0.0248 | T6: 0.4362 | U6: 0.1326 | V6: 0.2724 | W6: 0.0064 | X6: 0 | Y6: 0.0748 | Z6: 0.0108 | AA6: 0.958 | AC6: =IF(ISNUMBER(INDEX($A$2:$AA$14,5,MATCH(Arbitraj!$E$2,$A$1:$AA$1,0))),INDEX($A$2:$AA$14,5,MATCH(Arbitraj!$E$2,$A$1:$AA$1,0)),-1000000000)-ROW()/10000000 -> 0.24709751
A7: SST | B7: Strateji Portföy İstatistiksel Arbitraj Serbest Fon | C7: Strateji Portföy | D7: 0.03 | E7: 0.21290221 | F7: 0.42212813 | G7: 2.5332295 | H7: 16.406107 | I7: 34.045137 | J7: 22 | K7: 22 | L7: 0 | M7: 8987622.2 | N7: 9215302.9 | O7: 0.025332691 | P7: 0.11621171 | Q7: Görmüyor | R7: 0 | S7: 0.4624 | T7: 0 | U7: 0.5214 | V7: 0 | W7: 0 | X7: 0 | Y7: 0 | Z7: 0 | AA7: 0.9838 | AC7: =IF(ISNUMBER(INDEX($A$2:$AA$14,6,MATCH(Arbitraj!$E$2,$A$1:$AA$1,0))),INDEX($A$2:$AA$14,6,MATCH(Arbitraj!$E$2,$A$1:$AA$1,0)),-1000000000)-ROW()/10000000 -> 0.21290151
A8: MPI | B8: Meksa Portföy İstatistiksel Arbitraj Serbest (TL) Fon | C8: Meksa Portföy | D8: 0.02 | E8: 0.16491231 | F8: 0.76124045 | G8: 3.0372908 | H8: 21.226 | I8: 44.148714 | J8: 35 | K8: 34 | L8: -0.028571429 | M8: 76274280 | N8: 75635369 | O8: -0.0083764849 | P8: 0.11107127 | Q8: Görüyor | R8: 0 | S8: 0.1006 | T8: 0 | U8: 0.5279 | V8: 0.2512 | W8: 0 | X8: 0.0572 | Y8: 0.0631 | Z8: 0 | AA8: 1 | AC8: =IF(ISNUMBER(INDEX($A$2:$AA$14,7,MATCH(Arbitraj!$E$2,$A$1:$AA$1,0))),INDEX($A$2:$AA$14,7,MATCH(Arbitraj!$E$2,$A$1:$AA$1,0)),-1000000000)-ROW()/10000000 -> 0.16491151
A9: NIS | B9: Neo Portföy İstatistiksel Arbitraj Serbest Fon | C9: Neo Portföy | D9: 0.015 | E9: 0.13565284 | F9: 0.83867845 | G9: 3.8008718 | H9: 23.412185 | I9: 52.248878 | J9: 24 | K9: 26 | L9: 0.083333333 | M9: 1.0868297e+09 | N9: 1.4793322e+09 | O9: 0.36114438 | P9: 0.051375268 | Q9: Görmüyor | R9: 0 | S9: 0.1973 | T9: 0 | U9: 0.1657 | V9: 0.4378 | W9: 0.1992 | X9: 0 | Y9: 0 | Z9: 0 | AA9: 1 | AC9: =IF(ISNUMBER(INDEX($A$2:$AA$14,8,MATCH(Arbitraj!$E$2,$A$1:$AA$1,0))),INDEX($A$2:$AA$14,8,MATCH(Arbitraj!$E$2,$A$1:$AA$1,0)),-1000000000)-ROW()/10000000 -> 0.13565194
A10: INZ | B10: Inveo Portföy İstatistiksel Arbitraj Serbest (TL) Fon | C10: Inveo Portföy | D10: 0.04 | E10: 0.13490678 | F10: 0.34534479 | G10: 3.1833473 | H10: 18.149871 | I10: 34.046446 | J10: 15 | K10: 15 | L10: 0 | M10: 1.1031609e+08 | N10: 1.1382782e+08 | O10: 0.031833322 | P10: 0.12410424 | Q10: Görmüyor | R10: 0 | S10: 0.1906 | T10: 0 | U10: 0.1466 | V10: 0.616 | W10: 0.0468 | X10: 0 | Y10: 0 | Z10: 0 | AA10: 1 | AC10: =IF(ISNUMBER(INDEX($A$2:$AA$14,9,MATCH(Arbitraj!$E$2,$A$1:$AA$1,0))),INDEX($A$2:$AA$14,9,MATCH(Arbitraj!$E$2,$A$1:$AA$1,0)),-1000000000)-ROW()/10000000 -> 0.13490578
A11: AC5 | B11: Pardus Portföy İstatistiksel Arbitraj Hisse Senedi Serbest (TL) Fon (Hisse Senedi Yoğun Fon) | C11: Pardus Portföy | D11: 0.015 | E11: 0.13120767 | F11: 0.65602274 | G11: 2.432806 | H11: 16.774915 | I11: 37.519523 | J11: 159 | K11: 147 | L11: -0.075471698 | M11: 21318577 | N11: 21779407 | O11: 0.021616396 | P11: 0.1496238 | Q11: Görüyor | R11: 0 | S11: 0.1953 | T11: 0 | U11: 0.8047 | V11: 0 | W11: 0 | X11: 0 | Y11: 0 | Z11: 0 | AA11: 1 | AC11: =IF(ISNUMBER(INDEX($A$2:$AA$14,10,MATCH(Arbitraj!$E$2,$A$1:$AA$1,0))),INDEX($A$2:$AA$14,10,MATCH(Arbitraj!$E$2,$A$1:$AA$1,0)),-1000000000)-ROW()/10000000 -> 0.13120657
A12: OFB | B12: Oyak Portföy İstatistiksel Arbitraj Serbest (TL) Fon | C12: Oyak Portföy | D12: 0.005 | E12: 0.12168723 | F12: 0.74531816 | G12: 3.450755 | H12: 22.280029 | I12: 46.764647 | J12: 13 | K12: 13 | L12: 0 | M12: 9.4812935e+08 | N12: 9.7525645e+08 | O12: 0.028611174 | P12: 0.077584275 | Q12: Görmüyor | R12: 0 | S12: 0.0747 | T12: 0.9247 | U12: 0 | V12: 0.0006 | W12: 0 | X12: 0 | Y12: 0 | Z12: 0 | AA12: 1 | AC12: =IF(ISNUMBER(INDEX($A$2:$AA$14,11,MATCH(Arbitraj!$E$2,$A$1:$AA$1,0))),INDEX($A$2:$AA$14,11,MATCH(Arbitraj!$E$2,$A$1:$AA$1,0)),-1000000000)-ROW()/10000000 -> 0.12168603
A13: DPI | B13: Deniz Portföy İstatistiksel Arbitraj Hisse Senedi Serbest Fon (Hisse Senedi Yoğun Fon) | C13: Deniz Portföy | D13: 0.0325 | E13: 0.035155975 | F13: 0.63732318 | G13: 2.4946599 | H13: 19.813222 | I13: 41.457413 | J13: 120 | K13: 121 | L13: 0.0083333333 | M13: 3.5755997e+08 | N13: 3.6093876e+08 | O13: 0.0094495859 | P13: 0.092173479 | Q13: Görüyor | R13: 0.0022 | S13: 0.1368 | T13: 0 | U13: 0.8957 | V13: 0 | W13: 0 | X13: 0 | Y13: 0 | Z13: 0 | AA13: 1.0347 | AC13: =IF(ISNUMBER(INDEX($A$2:$AA$14,12,MATCH(Arbitraj!$E$2,$A$1:$AA$1,0))),INDEX($A$2:$AA$14,12,MATCH(Arbitraj!$E$2,$A$1:$AA$1,0)),-1000000000)-ROW()/10000000 -> 0.035154675
A14: UZY | B14: Ünlü Portföy İkinci İstatistiksel Arbitraj Serbest Fon | C14: Ünlü Portföy | D14: 0.03 | E14: -0.035231897 | F14: 0.56923257 | G14: 434.52364 | H14: 86.579077 | I14: 120.66541 | J14: 16 | K14: 32 | L14: 1 | M14: 52088.23 | N14: 1.4358243e+08 | O14: 2755.5235 | P14: 0.12751642 | Q14: Görmüyor | R14: 0 | S14: 0 | T14: 0.8466 | U14: 0.1499 | V14: 0.0035 | W14: 0 | X14: 0 | Y14: 0 | Z14: 0 | AA14: 1 | AC14: =IF(ISNUMBER(INDEX($A$2:$AA$14,13,MATCH(Arbitraj!$E$2,$A$1:$AA$1,0))),INDEX($A$2:$AA$14,13,MATCH(Arbitraj!$E$2,$A$1:$AA$1,0)),-1000000000)-ROW()/10000000 -> -0.035233297

Sheet Arbitraj
F1: 46216 | G1: 46210 | H1: 46185 | I1: 46022 | J1: 45852
B2: T-1: 14.07.2026 | D2: Sırala: | E2: Günlük%
B3: Fon Kodu | C3: Arbitraj Fonları | D3: Yönetici | E3: FYÜ% | F3: Günlük% | G3: Haftalık | H3: Aylık | I3: Yılbaşına Göre | J3: Yıllık | K3: Yatırımcı Sayısı T-30 | L3: Yatırımcı Sayısı T-1 | M3: YS Değişim | N3: Önceki Ay FTD | O3: T-1 FTD | P3: FTD Değişim | Q3: Standart Sapma (Aylık) | R3: TEFAS Durumu | S3: Mevduat (TL) | T3: Vadeli İşlemler Nakit Teminatları | U3: Ters Repo Oranı | V3: Hisse Oranı | W3: Para Piyasaları Oranı | X3: Yatırım Fonları Katılma Payları | Y3: Özel Tahvil/Bono Oranı | Z3: Finansman Bonosu Oranı | AA3: Diğer Oran | AB3: Toplam
A4: 1 | B4: =INDEX(V_Arbitraj!A$2:A$14,MATCH(LARGE(V_Arbitraj!$AC$2:$AC$14,ROW()-3),V_Arbitraj!$AC$2:$AC$14,0)) -> ICN | C4: =INDEX(V_Arbitraj!B$2:B$14,MATCH(LARGE(V_Arbitraj!$AC$2:$AC$14,ROW()-3),V_Arbitraj!$AC$2:$AC$14,0)) -> İstanbul Portföy Üçüncü İstatistiksel Arbitraj Serbest (TL) Fon | D4: =INDEX(V_Arbitraj!C$2:C$14,MATCH(LARGE(V_Arbitraj!$AC$2:$AC$14,ROW()-3),V_Arbitraj!$AC$2:$AC$14,0)) -> İstanbul Portföy | E4: =INDEX(V_Arbitraj!D$2:D$14,MATCH(LARGE(V_Arbitraj!$AC$2:$AC$14,ROW()-3),V_Arbitraj!$AC$2:$AC$14,0)) -> 0.0315 | F4: =INDEX(V_Arbitraj!E$2:E$14,MATCH(LARGE(V_Arbitraj!$AC$2:$AC$14,ROW()-3),V_Arbitraj!$AC$2:$AC$14,0)) -> 0.47122477 | G4: =INDEX(V_Arbitraj!F$2:F$14,MATCH(LARGE(V_Arbitraj!$AC$2:$AC$14,ROW()-3),V_Arbitraj!$AC$2:$AC$14,0)) -> 0.81708437 | H4: =INDEX(V_Arbitraj!G$2:G$14,MATCH(LARGE(V_Arbitraj!$AC$2:$AC$14,ROW()-3),V_Arbitraj!$AC$2:$AC$14,0)) -> 3.2703729 | I4: =INDEX(V_Arbitraj!H$2:H$14,MATCH(LARGE(V_Arbitraj!$AC$2:$AC$14,ROW()-3),V_Arbitraj!$AC$2:$AC$14,0)) -> 25.837835 | ... AB4: =INDEX(V_Arbitraj!AA$2:AA$14,MATCH(LARGE(V_Arbitraj!$AC$2:$AC$14,ROW()-3),V_Arbitraj!$AC$2:$AC$14,0)) -> 0.9994
A5: 2 | B5: =INDEX(V_Arbitraj!A$2:A$14,MATCH(LARGE(V_Arbitraj!$AC$2:$AC$14,ROW()-3),V_Arbitraj!$AC$2:$AC$14,0)) -> IRV | C5: =INDEX(V_Arbitraj!B$2:B$14,MATCH(LARGE(V_Arbitraj!$AC$2:$AC$14,ROW()-3),V_Arbitraj!$AC$2:$AC$14,0)) -> İstanbul Portföy İstatistiksel Arbitraj Serbest Fon | D5: =INDEX(V_Arbitraj!C$2:C$14,MATCH(LARGE(V_Arbitraj!$AC$2:$AC$14,ROW()-3),V_Arbitraj!$AC$2:$AC$14,0)) -> İstanbul Portföy | E5: =INDEX(V_Arbitraj!D$2:D$14,MATCH(LARGE(V_Arbitraj!$AC$2:$AC$14,ROW()-3),V_Arbitraj!$AC$2:$AC$14,0)) -> 0.03 | F5: =INDEX(V_Arbitraj!E$2:E$14,MATCH(LARGE(V_Arbitraj!$AC$2:$AC$14,ROW()-3),V_Arbitraj!$AC$2:$AC$14,0)) -> 0.29038708 | G5: =INDEX(V_Arbitraj!F$2:F$14,MATCH(LARGE(V_Arbitraj!$AC$2:$AC$14,ROW()-3),V_Arbitraj!$AC$2:$AC$14,0)) -> 0.61558927 | H5: =INDEX(V_Arbitraj!G$2:G$14,MATCH(LARGE(V_Arbitraj!$AC$2:$AC$14,ROW()-3),V_Arbitraj!$AC$2:$AC$14,0)) -> 3.87085 | I5: =INDEX(V_Arbitraj!H$2:H$14,MATCH(LARGE(V_Arbitraj!$AC$2:$AC$14,ROW()-3),V_Arbitraj!$AC$2:$AC$14,0)) -> 18.470973 | ... AB5: =INDEX(V_Arbitraj!AA$2:AA$14,MATCH(LARGE(V_Arbitraj!$AC$2:$AC$14,ROW()-3),V_Arbitraj!$AC$2:$AC$14,0)) -> 0.9996
A6: 3 | B6: =INDEX(V_Arbitraj!A$2:A$14,MATCH(LARGE(V_Arbitraj!$AC$2:$AC$14,ROW()-3),V_Arbitraj!$AC$2:$AC$14,0)) -> LPH | C6: =INDEX(V_Arbitraj!B$2:B$14,MATCH(LARGE(V_Arbitraj!$AC$2:$AC$14,ROW()-3),V_Arbitraj!$AC$2:$AC$14,0)) -> Statech Portföy İstatistiksel Arbitraj Hisse Senedi Serbest (TL) Fon (Hisse Senedi Yoğun Fon) | D6: =INDEX(V_Arbitraj!C$2:C$14,MATCH(LARGE(V_Arbitraj!$AC$2:$AC$14,ROW()-3),V_Arbitraj!$AC$2:$AC$14,0)) -> Statech Portföy | E6: =INDEX(V_Arbitraj!D$2:D$14,MATCH(LARGE(V_Arbitraj!$AC$2:$AC$14,ROW()-3),V_Arbitraj!$AC$2:$AC$14,0)) -> 0.035 | F6: =INDEX(V_Arbitraj!E$2:E$14,MATCH(LARGE(V_Arbitraj!$AC$2:$AC$14,ROW()-3),V_Arbitraj!$AC$2:$AC$14,0)) -> 0.28554763 | G6: =INDEX(V_Arbitraj!F$2:F$14,MATCH(LARGE(V_Arbitraj!$AC$2:$AC$14,ROW()-3),V_Arbitraj!$AC$2:$AC$14,0)) -> 0.95667656 | H6: =INDEX(V_Arbitraj!G$2:G$14,MATCH(LARGE(V_Arbitraj!$AC$2:$AC$14,ROW()-3),V_Arbitraj!$AC$2:$AC$14,0)) -> 3.4575854 | I6: =INDEX(V_Arbitraj!H$2:H$14,MATCH(LARGE(V_Arbitraj!$AC$2:$AC$14,ROW()-3),V_Arbitraj!$AC$2:$AC$14,0)) -> 31.611835 | ... AB6: =INDEX(V_Arbitraj!AA$2:AA$14,MATCH(LARGE(V_Arbitraj!$AC$2:$AC$14,ROW()-3),V_Arbitraj!$AC$2:$AC$14,0)) -> 1
A7: 4 | B7: =INDEX(V_Arbitraj!A$2:A$14,MATCH(LARGE(V_Arbitraj!$AC$2:$AC$14,ROW()-3),V_Arbitraj!$AC$2:$AC$14,0)) -> TCI | C7: =INDEX(V_Arbitraj!B$2:B$14,MATCH(LARGE(V_Arbitraj!$AC$2:$AC$14,ROW()-3),V_Arbitraj!$AC$2:$AC$14,0)) -> Tacirler Portföy İstatistiksel Arbitraj Serbest Fon | D7: =INDEX(V_Arbitraj!C$2:C$14,MATCH(LARGE(V_Arbitraj!$AC$2:$AC$14,ROW()-3),V_Arbitraj!$AC$2:$AC$14,0)) -> Tacirler Portföy | E7: =INDEX(V_Arbitraj!D$2:D$14,MATCH(LARGE(V_Arbitraj!$AC$2:$AC$14,ROW()-3),V_Arbitraj!$AC$2:$AC$14,0)) -> 0.035 | F7: =INDEX(V_Arbitraj!E$2:E$14,MATCH(LARGE(V_Arbitraj!$AC$2:$AC$14,ROW()-3),V_Arbitraj!$AC$2:$AC$14,0)) -> 0.26090605 | G7: =INDEX(V_Arbitraj!F$2:F$14,MATCH(LARGE(V_Arbitraj!$AC$2:$AC$14,ROW()-3),V_Arbitraj!$AC$2:$AC$14,0)) -> 0.70593745 | H7: =INDEX(V_Arbitraj!G$2:G$14,MATCH(LARGE(V_Arbitraj!$AC$2:$AC$14,ROW()-3),V_Arbitraj!$AC$2:$AC$14,0)) -> 3.2436742 | I7: =INDEX(V_Arbitraj!H$2:H$14,MATCH(LARGE(V_Arbitraj!$AC$2:$AC$14,ROW()-3),V_Arbitraj!$AC$2:$AC$14,0)) -> 21.828324 | ... AB7: =INDEX(V_Arbitraj!AA$2:AA$14,MATCH(LARGE(V_Arbitraj!$AC$2:$AC$14,ROW()-3),V_Arbitraj!$AC$2:$AC$14,0)) -> 1
A8: 5 | B8: =INDEX(V_Arbitraj!A$2:A$14,MATCH(LARGE(V_Arbitraj!$AC$2:$AC$14,ROW()-3),V_Arbitraj!$AC$2:$AC$14,0)) -> BVZ | C8: =INDEX(V_Arbitraj!B$2:B$14,MATCH(LARGE(V_Arbitraj!$AC$2:$AC$14,ROW()-3),V_Arbitraj!$AC$2:$AC$14,0)) -> BV Portföy İstatistiksel Arbitraj Serbest (TL) Fon | D8: =INDEX(V_Arbitraj!C$2:C$14,MATCH(LARGE(V_Arbitraj!$AC$2:$AC$14,ROW()-3),V_Arbitraj!$AC$2:$AC$14,0)) -> BV Portföy | E8: =INDEX(V_Arbitraj!D$2:D$14,MATCH(LARGE(V_Arbitraj!$AC$2:$AC$14,ROW()-3),V_Arbitraj!$AC$2:$AC$14,0)) -> 0.042 | F8: =INDEX(V_Arbitraj!E$2:E$14,MATCH(LARGE(V_Arbitraj!$AC$2:$AC$14,ROW()-3),V_Arbitraj!$AC$2:$AC$14,0)) -> 0.24709811 | G8: =INDEX(V_Arbitraj!F$2:F$14,MATCH(LARGE(V_Arbitraj!$AC$2:$AC$14,ROW()-3),V_Arbitraj!$AC$2:$AC$14,0)) -> 0.86947754 | H8: =INDEX(V_Arbitraj!G$2:G$14,MATCH(LARGE(V_Arbitraj!$AC$2:$AC$14,ROW()-3),V_Arbitraj!$AC$2:$AC$14,0)) -> 3.5748564 | I8: =INDEX(V_Arbitraj!H$2:H$14,MATCH(LARGE(V_Arbitraj!$AC$2:$AC$14,ROW()-3),V_Arbitraj!$AC$2:$AC$14,0)) -> 23.814921 | ... AB8: =INDEX(V_Arbitraj!AA$2:AA$14,MATCH(LARGE(V_Arbitraj!$AC$2:$AC$14,ROW()-3),V_Arbitraj!$AC$2:$AC$14,0)) -> 0.958
A9: 6 | B9: =INDEX(V_Arbitraj!A$2:A$14,MATCH(LARGE(V_Arbitraj!$AC$2:$AC$14,ROW()-3),V_Arbitraj!$AC$2:$AC$14,0)) -> SST | C9: =INDEX(V_Arbitraj!B$2:B$14,MATCH(LARGE(V_Arbitraj!$AC$2:$AC$14,ROW()-3),V_Arbitraj!$AC$2:$AC$14,0)) -> Strateji Portföy İstatistiksel Arbitraj Serbest Fon | D9: =INDEX(V_Arbitraj!C$2:C$14,MATCH(LARGE(V_Arbitraj!$AC$2:$AC$14,ROW()-3),V_Arbitraj!$AC$2:$AC$14,0)) -> Strateji Portföy | E9: =INDEX(V_Arbitraj!D$2:D$14,MATCH(LARGE(V_Arbitraj!$AC$2:$AC$14,ROW()-3),V_Arbitraj!$AC$2:$AC$14,0)) -> 0.03 | F9: =INDEX(V_Arbitraj!E$2:E$14,MATCH(LARGE(V_Arbitraj!$AC$2:$AC$14,ROW()-3),V_Arbitraj!$AC$2:$AC$14,0)) -> 0.21290221 | G9: =INDEX(V_Arbitraj!F$2:F$14,MATCH(LARGE(V_Arbitraj!$AC$2:$AC$14,ROW()-3),V_Arbitraj!$AC$2:$AC$14,0)) -> 0.42212813 | H9: =INDEX(V_Arbitraj!G$2:G$14,MATCH(LARGE(V_Arbitraj!$AC$2:$AC$14,ROW()-3),V_Arbitraj!$AC$2:$AC$14,0)) -> 2.5332295 | I9: =INDEX(V_Arbitraj!H$2:H$14,MATCH(LARGE(V_Arbitraj!$AC$2:$AC$14,ROW()-3),V_Arbitraj!$AC$2:$AC$14,0)) -> 16.406107 | ... AB9: =INDEX(V_Arbitraj!AA$2:AA$14,MATCH(LARGE(V_Arbitraj!$AC$2:$AC$14,ROW()-3),V_Arbitraj!$AC$2:$AC$14,0)) -> 0.9838
A10: 7 | B10: =INDEX(V_Arbitraj!A$2:A$14,MATCH(LARGE(V_Arbitraj!$AC$2:$AC$14,ROW()-3),V_Arbitraj!$AC$2:$AC$14,0)) -> MPI | C10: =INDEX(V_Arbitraj!B$2:B$14,MATCH(LARGE(V_Arbitraj!$AC$2:$AC$14,ROW()-3),V_Arbitraj!$AC$2:$AC$14,0)) -> Meksa Portföy İstatistiksel Arbitraj Serbest (TL) Fon | D10: =INDEX(V_Arbitraj!C$2:C$14,MATCH(LARGE(V_Arbitraj!$AC$2:$AC$14,ROW()-3),V_Arbitraj!$AC$2:$AC$14,0)) -> Meksa Portföy | E10: =INDEX(V_Arbitraj!D$2:D$14,MATCH(LARGE(V_Arbitraj!$AC$2:$AC$14,ROW()-3),V_Arbitraj!$AC$2:$AC$14,0)) -> 0.02 | F10: =INDEX(V_Arbitraj!E$2:E$14,MATCH(LARGE(V_Arbitraj!$AC$2:$AC$14,ROW()-3),V_Arbitraj!$AC$2:$AC$14,0)) -> 0.16491231 | G10: =INDEX(V_Arbitraj!F$2:F$14,MATCH(LARGE(V_Arbitraj!$AC$2:$AC$14,ROW()-3),V_Arbitraj!$AC$2:$AC$14,0)) -> 0.76124045 | H10: =INDEX(V_Arbitraj!G$2:G$14,MATCH(LARGE(V_Arbitraj!$AC$2:$AC$14,ROW()-3),V_Arbitraj!$AC$2:$AC$14,0)) -> 3.0372908 | I10: =INDEX(V_Arbitraj!H$2:H$14,MATCH(LARGE(V_Arbitraj!$AC$2:$AC$14,ROW()-3),V_Arbitraj!$AC$2:$AC$14,0)) -> 21.226 | ... AB10: =INDEX(V_Arbitraj!AA$2:AA$14,MATCH(LARGE(V_Arbitraj!$AC$2:$AC$14,ROW()-3),V_Arbitraj!$AC$2:$AC$14,0)) -> 1
A11: 8 | B11: =INDEX(V_Arbitraj!A$2:A$14,MATCH(LARGE(V_Arbitraj!$AC$2:$AC$14,ROW()-3),V_Arbitraj!$AC$2:$AC$14,0)) -> NIS | C11: =INDEX(V_Arbitraj!B$2:B$14,MATCH(LARGE(V_Arbitraj!$AC$2:$AC$14,ROW()-3),V_Arbitraj!$AC$2:$AC$14,0)) -> Neo Portföy İstatistiksel Arbitraj Serbest Fon | D11: =INDEX(V_Arbitraj!C$2:C$14,MATCH(LARGE(V_Arbitraj!$AC$2:$AC$14,ROW()-3),V_Arbitraj!$AC$2:$AC$14,0)) -> Neo Portföy | E11: =INDEX(V_Arbitraj!D$2:D$14,MATCH(LARGE(V_Arbitraj!$AC$2:$AC$14,ROW()-3),V_Arbitraj!$AC$2:$AC$14,0)) -> 0.015 | F11: =INDEX(V_Arbitraj!E$2:E$14,MATCH(LARGE(V_Arbitraj!$AC$2:$AC$14,ROW()-3),V_Arbitraj!$AC$2:$AC$14,0)) -> 0.13565284 | G11: =INDEX(V_Arbitraj!F$2:F$14,MATCH(LARGE(V_Arbitraj!$AC$2:$AC$14,ROW()-3),V_Arbitraj!$AC$2:$AC$14,0)) -> 0.83867845 | H11: =INDEX(V_Arbitraj!G$2:G$14,MATCH(LARGE(V_Arbitraj!$AC$2:$AC$14,ROW()-3),V_Arbitraj!$AC$2:$AC$14,0)) -> 3.8008718 | I11: =INDEX(V_Arbitraj!H$2:H$14,MATCH(LARGE(V_Arbitraj!$AC$2:$AC$14,ROW()-3),V_Arbitraj!$AC$2:$AC$14,0)) -> 23.412185 | ... AB11: =INDEX(V_Arbitraj!AA$2:AA$14,MATCH(LARGE(V_Arbitraj!$AC$2:$AC$14,ROW()-3),V_Arbitraj!$AC$2:$AC$14,0)) -> 1
A12: 9 | B12: =INDEX(V_Arbitraj!A$2:A$14,MATCH(LARGE(V_Arbitraj!$AC$2:$AC$14,ROW()-3),V_Arbitraj!$AC$2:$AC$14,0)) -> INZ | C12: =INDEX(V_Arbitraj!B$2:B$14,MATCH(LARGE(V_Arbitraj!$AC$2:$AC$14,ROW()-3),V_Arbitraj!$AC$2:$AC$14,0)) -> Inveo Portföy İstatistiksel Arbitraj Serbest (TL) Fon | D12: =INDEX(V_Arbitraj!C$2:C$14,MATCH(LARGE(V_Arbitraj!$AC$2:$AC$14,ROW()-3),V_Arbitraj!$AC$2:$AC$14,0)) -> Inveo Portföy | E12: =INDEX(V_Arbitraj!D$2:D$14,MATCH(LARGE(V_Arbitraj!$AC$2:$AC$14,ROW()-3),V_Arbitraj!$AC$2:$AC$14,0)) -> 0.04 | F12: =INDEX(V_Arbitraj!E$2:E$14,MATCH(LARGE(V_Arbitraj!$AC$2:$AC$14,ROW()-3),V_Arbitraj!$AC$2:$AC$14,0)) -> 0.13490678 | G12: =INDEX(V_Arbitraj!F$2:F$14,MATCH(LARGE(V_Arbitraj!$AC$2:$AC$14,ROW()-3),V_Arbitraj!$AC$2:$AC$14,0)) -> 0.34534479 | H12: =INDEX(V_Arbitraj!G$2:G$14,MATCH(LARGE(V_Arbitraj!$AC$2:$AC$14,ROW()-3),V_Arbitraj!$AC$2:$AC$14,0)) -> 3.1833473 | I12: =INDEX(V_Arbitraj!H$2:H$14,MATCH(LARGE(V_Arbitraj!$AC$2:$AC$14,ROW()-3),V_Arbitraj!$AC$2:$AC$14,0)) -> 18.149871 | ... AB12: =INDEX(V_Arbitraj!AA$2:AA$14,MATCH(LARGE(V_Arbitraj!$AC$2:$AC$14,ROW()-3),V_Arbitraj!$AC$2:$AC$14,0)) -> 1
A13: 10 | B13: =INDEX(V_Arbitraj!A$2:A$14,MATCH(LARGE(V_Arbitraj!$AC$2:$AC$14,ROW()-3),V_Arbitraj!$AC$2:$AC$14,0)) -> AC5 | C13: =INDEX(V_Arbitraj!B$2:B$14,MATCH(LARGE(V_Arbitraj!$AC$2:$AC$14,ROW()-3),V_Arbitraj!$AC$2:$AC$14,0)) -> Pardus Portföy İstatistiksel Arbitraj Hisse Senedi Serbest (TL) Fon (Hisse Senedi Yoğun Fon) | D13: =INDEX(V_Arbitraj!C$2:C$14,MATCH(LARGE(V_Arbitraj!$AC$2:$AC$14,ROW()-3),V_Arbitraj!$AC$2:$AC$14,0)) -> Pardus Portföy | E13: =INDEX(V_Arbitraj!D$2:D$14,MATCH(LARGE(V_Arbitraj!$AC$2:$AC$14,ROW()-3),V_Arbitraj!$AC$2:$AC$14,0)) -> 0.015 | F13: =INDEX(V_Arbitraj!E$2:E$14,MATCH(LARGE(V_Arbitraj!$AC$2:$AC$14,ROW()-3),V_Arbitraj!$AC$2:$AC$14,0)) -> 0.13120767 | G13: =INDEX(V_Arbitraj!F$2:F$14,MATCH(LARGE(V_Arbitraj!$AC$2:$AC$14,ROW()-3),V_Arbitraj!$AC$2:$AC$14,0)) -> 0.65602274 | H13: =INDEX(V_Arbitraj!G$2:G$14,MATCH(LARGE(V_Arbitraj!$AC$2:$AC$14,ROW()-3),V_Arbitraj!$AC$2:$AC$14,0)) -> 2.432806 | I13: =INDEX(V_Arbitraj!H$2:H$14,MATCH(LARGE(V_Arbitraj!$AC$2:$AC$14,ROW()-3),V_Arbitraj!$AC$2:$AC$14,0)) -> 16.774915 | ... AB13: =INDEX(V_Arbitraj!AA$2:AA$14,MATCH(LARGE(V_Arbitraj!$AC$2:$AC$14,ROW()-3),V_Arbitraj!$AC$2:$AC$14,0)) -> 1
A14: 11 | B14: =INDEX(V_Arbitraj!A$2:A$14,MATCH(LARGE(V_Arbitraj!$AC$2:$AC$14,ROW()-3),V_Arbitraj!$AC$2:$AC$14,0)) -> OFB | C14: =INDEX(V_Arbitraj!B$2:B$14,MATCH(LARGE(V_Arbitraj!$AC$2:$AC$14,ROW()-3),V_Arbitraj!$AC$2:$AC$14,0)) -> Oyak Portföy İstatistiksel Arbitraj Serbest (TL) Fon | D14: =INDEX(V_Arbitraj!C$2:C$14,MATCH(LARGE(V_Arbitraj!$AC$2:$AC$14,ROW()-3),V_Arbitraj!$AC$2:$AC$14,0)) -> Oyak Portföy | E14: =INDEX(V_Arbitraj!D$2:D$14,MATCH(LARGE(V_Arbitraj!$AC$2:$AC$14,ROW()-3),V_Arbitraj!$AC$2:$AC$14,0)) -> 0.005 | F14: =INDEX(V_Arbitraj!E$2:E$14,MATCH(LARGE(V_Arbitraj!$AC$2:$AC$14,ROW()-3),V_Arbitraj!$AC$2:$AC$14,0)) -> 0.12168723 | G14: =INDEX(V_Arbitraj!F$2:F$14,MATCH(LARGE(V_Arbitraj!$AC$2:$AC$14,ROW()-3),V_Arbitraj!$AC$2:$AC$14,0)) -> 0.74531816 | H14: =INDEX(V_Arbitraj!G$2:G$14,MATCH(LARGE(V_Arbitraj!$AC$2:$AC$14,ROW()-3),V_Arbitraj!$AC$2:$AC$14,0)) -> 3.450755 | I14: =INDEX(V_Arbitraj!H$2:H$14,MATCH(LARGE(V_Arbitraj!$AC$2:$AC$14,ROW()-3),V_Arbitraj!$AC$2:$AC$14,0)) -> 22.280029 | ... AB14: =INDEX(V_Arbitraj!AA$2:AA$14,MATCH(LARGE(V_Arbitraj!$AC$2:$AC$14,ROW()-3),V_Arbitraj!$AC$2:$AC$14,0)) -> 1
A15: 12 | B15: =INDEX(V_Arbitraj!A$2:A$14,MATCH(LARGE(V_Arbitraj!$AC$2:$AC$14,ROW()-3),V_Arbitraj!$AC$2:$AC$14,0)) -> DPI | C15: =INDEX(V_Arbitraj!B$2:B$14,MATCH(LARGE(V_Arbitraj!$AC$2:$AC$14,ROW()-3),V_Arbitraj!$AC$2:$AC$14,0)) -> Deniz Portföy İstatistiksel Arbitraj Hisse Senedi Serbest Fon (Hisse Senedi Yoğun Fon) | D15: =INDEX(V_Arbitraj!C$2:C$14,MATCH(LARGE(V_Arbitraj!$AC$2:$AC$14,ROW()-3),V_Arbitraj!$AC$2:$AC$14,0)) -> Deniz Portföy | E15: =INDEX(V_Arbitraj!D$2:D$14,MATCH(LARGE(V_Arbitraj!$AC$2:$AC$14,ROW()-3),V_Arbitraj!$AC$2:$AC$14,0)) -> 0.0325 | F15: =INDEX(V_Arbitraj!E$2:E$14,MATCH(LARGE(V_Arbitraj!$AC$2:$AC$14,ROW()-3),V_Arbitraj!$AC$2:$AC$14,0)) -> 0.035155975 | G15: =INDEX(V_Arbitraj!F$2:F$14,MATCH(LARGE(V_Arbitraj!$AC$2:$AC$14,ROW()-3),V_Arbitraj!$AC$2:$AC$14,0)) -> 0.63732318 | H15: =INDEX(V_Arbitraj!G$2:G$14,MATCH(LARGE(V_Arbitraj!$AC$2:$AC$14,ROW()-3),V_Arbitraj!$AC$2:$AC$14,0)) -> 2.4946599 | I15: =INDEX(V_Arbitraj!H$2:H$14,MATCH(LARGE(V_Arbitraj!$AC$2:$AC$14,ROW()-3),V_Arbitraj!$AC$2:$AC$14,0)) -> 19.813222 | ... AB15: =INDEX(V_Arbitraj!AA$2:AA$14,MATCH(LARGE(V_Arbitraj!$AC$2:$AC$14,ROW()-3),V_Arbitraj!$AC$2:$AC$14,0)) -> 1.0347
A16: 13 | B16: =INDEX(V_Arbitraj!A$2:A$14,MATCH(LARGE(V_Arbitraj!$AC$2:$AC$14,ROW()-3),V_Arbitraj!$AC$2:$AC$14,0)) -> UZY | C16: =INDEX(V_Arbitraj!B$2:B$14,MATCH(LARGE(V_Arbitraj!$AC$2:$AC$14,ROW()-3),V_Arbitraj!$AC$2:$AC$14,0)) -> Ünlü Portföy İkinci İstatistiksel Arbitraj Serbest Fon | D16: =INDEX(V_Arbitraj!C$2:C$14,MATCH(LARGE(V_Arbitraj!$AC$2:$AC$14,ROW()-3),V_Arbitraj!$AC$2:$AC$14,0)) -> Ünlü Portföy | E16: =INDEX(V_Arbitraj!D$2:D$14,MATCH(LARGE(V_Arbitraj!$AC$2:$AC$14,ROW()-3),V_Arbitraj!$AC$2:$AC$14,0)) -> 0.03 | F16: =INDEX(V_Arbitraj!E$2:E$14,MATCH(LARGE(V_Arbitraj!$AC$2:$AC$14,ROW()-3),V_Arbitraj!$AC$2:$AC$14,0)) -> -0.035231897 | G16: =INDEX(V_Arbitraj!F$2:F$14,MATCH(LARGE(V_Arbitraj!$AC$2:$AC$14,ROW()-3),V_Arbitraj!$AC$2:$AC$14,0)) -> 0.56923257 | H16: =INDEX(V_Arbitraj!G$2:G$14,MATCH(LARGE(V_Arbitraj!$AC$2:$AC$14,ROW()-3),V_Arbitraj!$AC$2:$AC$14,0)) -> 434.52364 | I16: =INDEX(V_Arbitraj!H$2:H$14,MATCH(LARGE(V_Arbitraj!$AC$2:$AC$14,ROW()-3),V_Arbitraj!$AC$2:$AC$14,0)) -> 86.579077 | ... AB16: =INDEX(V_Arbitraj!AA$2:AA$14,MATCH(LARGE(V_Arbitraj!$AC$2:$AC$14,ROW()-3),V_Arbitraj!$AC$2:$AC$14,0)) -> 1

Sheet V_Mutlak Getiri
A1: Fon Kodu | B1: Mutlak Getiri Fonları | C1: Yönetici | D1: FYÜ% | E1: Günlük% | F1: Haftalık | G1: Aylık | H1: Yılbaşına Göre | I1: Yıllık | J1: Yatırımcı Sayısı T-30 | K1: Yatırımcı Sayısı T-1 | L1: YS Değişim | M1: Önceki Ay FTD | N1: T-1 FTD | O1: FTD Değişim | P1: Standart Sapma (Aylık) | Q1: TEFAS Durumu | R1: Mevduat (TL) | S1: Vadeli İşlemler Nakit Teminatları | T1: Ters Repo Oranı | U1: Hisse Oranı | V1: Para Piyasaları Oranı | W1: Yatırım Fonları Katılma Payları | X1: Özel Tahvil/Bono Oranı | Y1: Finansman Bonosu Oranı | Z1: Diğer Oran | AA1: Toplam
A2: ZBO | B2: Ziraat Portföy Mutlak Getiri Hedefli Hisse Senedi Serbest Fon (Hisse Senedi Yoğun Fon) | C2: Ziraat Portföy | D2: 0.025 | E2: 1.9492138 | F2: 1.7721178 | G2: 1.7123685 | H2: 16.043799 | I2: 21.34745 | J2: 236 | K2: 224 | L2: -0.050847458 | M2: 4.2819234e+08 | N2: 4.3996471e+08 | O2: 0.027493182 | P2: 0.71209864 | Q2: Görüyor | R2: 0 | S2: 0.1196 | T2: 0.0019 | U2: 0.8785 | V2: 0 | W2: 0 | X2: 0 | Y2: 0 | Z2: 0 | AA2: 1 | AC2: =IF(ISNUMBER(INDEX($A$2:$AA$25,1,MATCH('Mutlak Getiri'!$E$2,$A$1:$AA$1,0))),INDEX($A$2:$AA$25,1,MATCH('Mutlak Getiri'!$E$2,$A$1:$AA$1,0)),-1000000000)-ROW()/10000000 -> 1.9492136
A3: MUT | B3: Garanti Portföy Mutlak Getiri Hedefli Hisse Senedi Serbest Fon (Hisse Senedi Yoğun Fon) | C3: Garanti Portföy | D3: 0.025 | E3: 1.481044 | F3: 1.7560271 | G3: 0.23858356 | H3: 11.529715 | I3: 30.330121 | J3: 1617 | K3: 1488 | L3: -0.079777365 | M3: 9.5569491e+08 | N3: 8.2845251e+08 | O3: -0.13314124 | P3: 0.43467098 | Q3: Görüyor | R3: 0 | S3: 0.2014 | T3: 0 | U3: 0.7977 | V3: 0.0005 | W3: 0.0004 | X3: 0 | Y3: 0 | Z3: 0 | AA3: 1 | AC3: =IF(ISNUMBER(INDEX($A$2:$AA$25,2,MATCH('Mutlak Getiri'!$E$2,$A$1:$AA$1,0))),INDEX($A$2:$AA$25,2,MATCH('Mutlak Getiri'!$E$2,$A$1:$AA$1,0)),-1000000000)-ROW()/10000000 -> 1.4810437
A4: FYF | B4: Strateji Portföy Mutlak Getiri Hedefli Hisse Senedi Serbest Fon(hisse Senedi Yoğun) | C4: Strateji Portföy | D4: 0.025 | E4: 1.3986767 | F4: 1.2955648 | G4: 0.082116083 | H4: 8.8649762 | I4: 26.860719 | J4: 11 | K4: 11 | L4: 0 | M4: 36302541 | N4: 36332176 | O4: 0.00081632661 | P4: 0.40262568 | Q4: Görmüyor | R4: 0 | S4: 0.1952 | T4: 0 | U4: 0.8048 | V4: 0 | W4: 0 | X4: 0 | Y4: 0 | Z4: 0 | AA4: 1 | AC4: =IF(ISNUMBER(INDEX($A$2:$AA$25,3,MATCH('Mutlak Getiri'!$E$2,$A$1:$AA$1,0))),INDEX($A$2:$AA$25,3,MATCH('Mutlak Getiri'!$E$2,$A$1:$AA$1,0)),-1000000000)-ROW()/10000000 -> 1.3986763
A5: MGH | B5: Teb Portföy Mutlak Getiri Hedefli Hisse Senedi Serbest Fon (Hisse Senedi Yoğun Fon) | C5: Teb Portföy | D5: 0.025 | E5: 0.41892707 | F5: 0.35725354 | G5: 0.84961332 | H5: 10.692413 | I5: 26.111411 | J5: 799 | K5: 756 | L5: -0.053817272 | M5: 5.1599768e+08 | N5: 4.7466932e+08 | O5: -0.080094088 | P5: 0.31492924 | Q5: Görüyor | R5: 0.0046 | S5: 0.1633 | T5: 0 | U5: 0.8321 | V5: 0 | W5: 0 | X5: 0 | Y5: 0 | Z5: 0 | AA5: 1 | AC5: =IF(ISNUMBER(INDEX($A$2:$AA$25,4,MATCH('Mutlak Getiri'!$E$2,$A$1:$AA$1,0))),INDEX($A$2:$AA$25,4,MATCH('Mutlak Getiri'!$E$2,$A$1:$AA$1,0)),-1000000000)-ROW()/10000000 -> 0.41892657
A6: HMG | B6: Hsbc Pyş Mutlak Getiri Hedefli Hisse Senedi Serbest (TL) Fon(hisse Senedi Yoğun Fon) | C6: Hsbc Portföy | D6: 0.025 | E6: 0.33762205 | F6: 0.75440579 | G6: 3.0375912 | H6: 13.91474 | I6: 27.731743 | J6: 5574 | K6: 6253 | L6: 0.12181557 | M6: 4.3668118e+09 | N6: 6.9980435e+09 | O6: 0.60255212 | P6: 0.15620986 | Q6: Görüyor | R6: 0 | S6: 0.1373 | T6: 0 | U6: 0.8059 | V6: 0.0568 | W6: 0 | X6: 0 | Y6: 0 | Z6: 0 | AA6: 1 | AC6: =IF(ISNUMBER(INDEX($A$2:$AA$25,5,MATCH('Mutlak Getiri'!$E$2,$A$1:$AA$1,0))),INDEX($A$2:$AA$25,5,MATCH('Mutlak Getiri'!$E$2,$A$1:$AA$1,0)),-1000000000)-ROW()/10000000 -> 0.33762145
A7: MTG | B7: Deniz Portföy Mutlak Getiri Hedefli Hisse Senedi Serbest Fon (Hisse Senedi Yogun Fon) | C7: Deniz Portföy | D7: 0.02 | E7: 0.32713565 | F7: 1.2618476 | G7: 3.5013027 | H7: 17.8574 | I7: 35.491803 | J7: 191 | K7: 216 | L7: 0.13089005 | M7: 67826190 | N7: 1.4337562e+08 | O7: 1.1138682 | P7: 0.29768734 | Q7: Görüyor | R7: 0.0053 | S7: 0.1633 | T7: 0 | U7: 0.8278 | V7: 0.0036 | W7: 0 | X7: 0 | Y7: 0 | Z7: 0 | AA7: 1 | AC7: =IF(ISNUMBER(INDEX($A$2:$AA$25,6,MATCH('Mutlak Getiri'!$E$2,$A$1:$AA$1,0))),INDEX($A$2:$AA$25,6,MATCH('Mutlak Getiri'!$E$2,$A$1:$AA$1,0)),-1000000000)-ROW()/10000000 -> 0.32713495
A8: BHI | B8: BV Portföy Mutlak Getiri Hedefli Hisse Senedi Serbest (TL) Fon (Hisse Senedi Yoğun Fon) | C8: BV Portföy | D8: 0.0315 | E8: 0.26088992 | F8: 0.7929963 | G8: 3.1946899 | H8: 23.162877 | I8: 45.110929 | J8: 392 | K8: 419 | L8: 0.068877551 | M8: 1.2172715e+09 | N8: 1.6582624e+09 | O8: 0.36227817 | P8: 0.069113092 | Q8: Görüyor | R8: 0 | S8: 0.1183 | T8: 0 | U8: 0.7239 | V8: 0.0911 | W8: 0.0098 | X8: 0 | Y8: 0.0214 | Z8: 0 | AA8: 0.9645 | AC8: =IF(ISNUMBER(INDEX($A$2:$AA$25,7,MATCH('Mutlak Getiri'!$E$2,$A$1:$AA$1,0))),INDEX($A$2:$AA$25,7,MATCH('Mutlak Getiri'!$E$2,$A$1:$AA$1,0)),-1000000000)-ROW()/10000000 -> 0.26088912
A9: PPM | B9: Piramit Portföy Mutlak Getiri Hedefli Hisse Senedi Serbest Fon (Hisse Senedi Yoğun Fon) | C9: Piramit Portföy | D9: 0.021 | E9: 0.2455957 | F9: 0.70794727 | G9: 2.9798184 | H9: 20.639164 | I9: 43.99956 | J9: 176 | K9: 160 | L9: -0.090909091 | M9: 1.9917914e+08 | N9: 1.4904602e+08 | O9: -0.25169867 | P9: 0.1098545 | Q9: Görüyor | R9: 0 | S9: 0.1619 | T9: 0 | U9: 0.7711 | V9: 0.067 | W9: 0 | X9: 0 | Y9: 0 | Z9: 0 | AA9: 1 | AC9: =IF(ISNUMBER(INDEX($A$2:$AA$25,8,MATCH('Mutlak Getiri'!$E$2,$A$1:$AA$1,0))),INDEX($A$2:$AA$25,8,MATCH('Mutlak Getiri'!$E$2,$A$1:$AA$1,0)),-1000000000)-ROW()/10000000 -> 0.2455948
A10: YMH | B10: Yapı Kredi Portföy Mutlak Getiri Hedefli Hisse Senedi Serbest Fon (Hisse Senedi Yoğun Fon) | C10: Yapı Kredi Portföy | D10: 0.025 | E10: 0.24435881 | F10: 0.75507441 | G10: 2.7342877 | H10: 16.941572 | I10: 34.710576 | J10: 337 | K10: 324 | L10: -0.038575668 | M10: 4.9653936e+08 | N10: 4.6001258e+08 | O10: -0.07356272 | P10: 0.12551743 | Q10: Görüyor | R10: 0 | S10: 0.1529 | T10: 0 | U10: 0.8471 | V10: 0 | W10: 0 | X10: 0 | Y10: 0 | Z10: 0 | AA10: 1 | AC10: =IF(ISNUMBER(INDEX($A$2:$AA$25,9,MATCH('Mutlak Getiri'!$E$2,$A$1:$AA$1,0))),INDEX($A$2:$AA$25,9,MATCH('Mutlak Getiri'!$E$2,$A$1:$AA$1,0)),-1000000000)-ROW()/10000000 -> 0.24435781
A11: HIM | B11: Hedef Portföy İkinci Mutlak Getiri Hedefli Hisse Senedi Serbest Fon (Hisse Senedi Yoğun Fon) | C11: Hedef Portföy | D11: 0.0375 | E11: 0.23000999 | F11: 0.73601611 | G11: 2.5024083 | H11: 19.216482 | I11: 39.373227 | J11: 256 | K11: 228 | L11: -0.109375 | M11: 3.2637782e+08 | N11: 2.7981272e+08 | O11: -0.14267237 | P11: 0.094741695 | Q11: Görüyor | R11: 0 | S11: 0.062 | T11: 0 | U11: 0.8491 | V11: -0.2825 | W11: 0.2037 | X11: 0 | Y11: 0.1293 | Z11: -0.0001 | AA11: 0.9615 | AC11: =IF(ISNUMBER(INDEX($A$2:$AA$25,10,MATCH('Mutlak Getiri'!$E$2,$A$1:$AA$1,0))),INDEX($A$2:$AA$25,10,MATCH('Mutlak Getiri'!$E$2,$A$1:$AA$1,0)),-1000000000)-ROW()/10000000 -> 0.23000889
A12: HVN | B12: Hedef Portföy Mutlak Getiri Hedefli Hisse Senedi Serbest Fon (Hisse Senedi Yoğun Fon) | C12: Hedef Portföy | D12: 0.03 | E12: 0.20888717 | F12: 0.37808978 | G12: 0.77806535 | H12: 12.753732 | I12: 15.035409 | J12: 12 | K12: 12 | L12: 0 | M12: 5721873.8 | N12: 5766394.4 | O12: 0.0077807746 | P12: 0.17897 | Q12: Görmüyor | R12: 0 | S12: 0.1372 | T12: 0 | U12: 0.8225 | V12: 0 | W12: 0.0403 | X12: 0 | Y12: 0 | Z12: 0 | AA12: 1 | AC12: =IF(ISNUMBER(INDEX($A$2:$AA$25,11,MATCH('Mutlak Getiri'!$E$2,$A$1:$AA$1,0))),INDEX($A$2:$AA$25,11,MATCH('Mutlak Getiri'!$E$2,$A$1:$AA$1,0)),-1000000000)-ROW()/10000000 -> 0.20888597
A13: HDK | B13: Hedef Portföy Vega İstatistiksel Arbitraj Hisse Senedi Serbest Fon (Hisse Senedi Yoğun Fon) | C13: Hedef Portföy | D13: 0.05 | E13: 0.20658773 | F13: 0.62806026 | G13: 1.4120367 | H13: 13.751954 | I13: 29.539553 | J13: 141 | K13: 131 | L13: -0.070921986 | M13: 12059302 | N13: 12092221 | O13: 0.0027297143 | P13: 0.21344561 | Q13: Görüyor | R13: 0 | S13: 0.2107 | T13: 0 | U13: 0.7881 | V13: 0 | W13: 0.0012 | X13: 0 | Y13: 0 | Z13: 0 | AA13: 1 | AC13: =IF(ISNUMBER(INDEX($A$2:$AA$25,12,MATCH('Mutlak Getiri'!$E$2,$A$1:$AA$1,0))),INDEX($A$2:$AA$25,12,MATCH('Mutlak Getiri'!$E$2,$A$1:$AA$1,0)),-1000000000)-ROW()/10000000 -> 0.20658643
A14: HAT | B14: Hedef Portföy Atlas İstatistiksel Arbitraj Hisse Senedi Serbest Fon (Hisse Senedi Yoğun Fon) | C14: Hedef Portföy | D14: 0.04 | E14: 0.18778322 | F14: 0.4862458 | G14: 0.4941141 | H14: 11.563205 | I14: 28.827835 | J14: 104 | K14: 95 | L14: -0.086538462 | M14: 5603384.9 | N14: 5021970.7 | O14: -0.10376125 | P14: 0.27257193 | Q14: Görüyor | R14: 0 | S14: 0.1387 | T14: 0 | U14: 0.8613 | V14: 0 | W14: 0 | X14: 0 | Y14: 0 | Z14: 0 | AA14: 1 | AC14: =IF(ISNUMBER(INDEX($A$2:$AA$25,13,MATCH('Mutlak Getiri'!$E$2,$A$1:$AA$1,0))),INDEX($A$2:$AA$25,13,MATCH('Mutlak Getiri'!$E$2,$A$1:$AA$1,0)),-1000000000)-ROW()/10000000 -> 0.18778182
A15: HIS | B15: Hedef Portföy İkinci İstatistiksel Arbitraj Hisse Senedi Serbest Fon (Hisse Senedi Yoğun Fon) | C15: Hedef Portföy | D15: 0.03 | E15: 0.16430435 | F15: -0.38670011 | G15: -4.86366 | H15: -11.607927 | I15: -0.88345186 | J15: 12 | K15: 12 | L15: 0 | M15: 1378896.8 | N15: 1311831.8 | O15: -0.048636664 | P15: 0.60830612 | Q15: Görmüyor | R15: 0 | S15: 0.1743 | T15: 0 | U15: 0.8257 | V15: 0 | W15: 0 | X15: 0 | Y15: 0 | Z15: 0 | AA15: 1 | AC15: =IF(ISNUMBER(INDEX($A$2:$AA$25,14,MATCH('Mutlak Getiri'!$E$2,$A$1:$AA$1,0))),INDEX($A$2:$AA$25,14,MATCH('Mutlak Getiri'!$E$2,$A$1:$AA$1,0)),-1000000000)-ROW()/10000000 -> 0.16430285
A16: IAU | B16: Pardus Portföy İkinci İstatistiksel Arbitraj Hisse Senedi Serbest (TL) Fon (Hisse Senedi Yoğun Fon) | C16: Pardus Portföy | D16: 0.015 | E16: 0.1322994 | F16: 0.92091705 | G16: 2.5360555 | H16: 18.711228 | I16: 38.970697 | J16: 257 | K16: 236 | L16: -0.081712062 | M16: 35472965 | N16: 34591595 | O16: -0.024846242 | P16: 0.14579377 | Q16: Görüyor | R16: 0 | S16: 0.1658 | T16: 0 | U16: 0.8342 | V16: 0 | W16: 0 | X16: 0 | Y16: 0 | Z16: 0 | AA16: 1 | AC16: =IF(ISNUMBER(INDEX($A$2:$AA$25,15,MATCH('Mutlak Getiri'!$E$2,$A$1:$AA$1,0))),INDEX($A$2:$AA$25,15,MATCH('Mutlak Getiri'!$E$2,$A$1:$AA$1,0)),-1000000000)-ROW()/10000000 -> 0.1322978
A17: KIH | B17: Kare Portföy İstatistiksel Arbitraj Serbest Fon | C17: Kare Portföy | D17: 0.04 | E17: 0.1244869 | F17: 0.65235813 | G17: 3.0859843 | H17: 18.418742 | I17: 32.8921 | J17: 36 | K17: 27 | L17: -0.25 | M17: 55918968 | N17: 57641359 | O17: 0.030801547 | P17: 0.062805177 | Q17: Görüyor | R17: 0 | S17: 0.134 | T17: 0.866 | U17: 0 | V17: 0 | W17: 0 | X17: 0 | Y17: 0 | Z17: 0 | AA17: 1 | AC17: =IF(ISNUMBER(INDEX($A$2:$AA$25,16,MATCH('Mutlak Getiri'!$E$2,$A$1:$AA$1,0))),INDEX($A$2:$AA$25,16,MATCH('Mutlak Getiri'!$E$2,$A$1:$AA$1,0)),-1000000000)-ROW()/10000000 -> 0.1244852
A18: HEH | B18: Hedef Portföy Algo Everest İstatistiksel Arbitraj Hisse Senedi Serbest Fon (Hisse Senedi Yoğun Fon) | C18: Hedef Portföy | D18: 0.045 | E18: 0.10277912 | F18: 0.65867394 | G18: 3.3929801 | H18: 20.150447 | I18: 40.569252 | J18: 1653 | K18: 1590 | L18: -0.038112523 | M18: 6.618098e+08 | N18: 6.6726691e+08 | O18: 0.0082457295 | P18: 0.10969075 | Q18: Görüyor | R18: 0 | S18: 0.194 | T18: 0 | U18: 0.806 | V18: 0 | W18: 0 | X18: 0 | Y18: 0 | Z18: 0 | AA18: 1 | AC18: =IF(ISNUMBER(INDEX($A$2:$AA$25,17,MATCH('Mutlak Getiri'!$E$2,$A$1:$AA$1,0))),INDEX($A$2:$AA$25,17,MATCH('Mutlak Getiri'!$E$2,$A$1:$AA$1,0)),-1000000000)-ROW()/10000000 -> 0.10277732
A19: SPN | B19: Azimut Portföy İstatistiksel Arbitraj Hisse Senedi Serbest Fon (Hisse Senedi Yoğun Fon) | C19: Azimut Portföy | D19: 0.032 | E19: 0.077396941 | F19: 0.62015406 | G19: 2.3356662 | H19: 18.552549 | I19: 39.604152 | J19: 427 | K19: 399 | L19: -0.06557377 | M19: 1.8197439e+09 | N19: 1.8358422e+09 | O19: 0.0088464551 | P19: 0.18783413 | Q19: Görüyor | R19: 0 | S19: 0.0615 | T19: 0 | U19: 0.8127 | V19: 0 | W19: 0.0142 | X19: 0.0228 | Y19: 0.2337 | Z19: 0 | AA19: 1.1449 | AC19: =IF(ISNUMBER(INDEX($A$2:$AA$25,18,MATCH('Mutlak Getiri'!$E$2,$A$1:$AA$1,0))),INDEX($A$2:$AA$25,18,MATCH('Mutlak Getiri'!$E$2,$A$1:$AA$1,0)),-1000000000)-ROW()/10000000 -> 0.077395041
A20: LTC | B20: AK Portföy Birinci İstatistiksel Arbitraj Hisse Senedi Serbest Fon (Hisse Senedi Yoğun Fon) | C20: AK Portföy | D20: 0.015 | E20: 0.023914023 | F20: 0.93286155 | G20: 2.2445192 | H20: 17.693521 | I20: 38.493545 | J20: 356 | K20: 338 | L20: -0.050561798 | M20: 15414332 | N20: 15468526 | O20: 0.003515832 | P20: 0.19027612 | Q20: Görmüyor | R20: 0 | S20: 0.1207 | T20: 0 | U20: 0.8621 | V20: 0.0172 | W20: 0 | X20: 0 | Y20: 0 | Z20: 0 | AA20: 1 | AC20: =IF(ISNUMBER(INDEX($A$2:$AA$25,19,MATCH('Mutlak Getiri'!$E$2,$A$1:$AA$1,0))),INDEX($A$2:$AA$25,19,MATCH('Mutlak Getiri'!$E$2,$A$1:$AA$1,0)),-1000000000)-ROW()/10000000 -> 0.023912023
A21: MTF | B21: MT Portföy Birinci İstatistiksel Arbitraj Hisse Senedi Serbest (TL) Fon (Hisse Senedi Yoğun Fon) | C21: MT Portföy | D21: 0.0315 | E21: -0.043452796 | F21: 0.61025944 | G21: 1.8756122 | H21: 17.35533 | I21: 32.885594 | J21: 43 | K21: 43 | L21: 0 | M21: 66666618 | N21: 68828666 | O21: 0.032430733 | P21: 0.20111589 | Q21: Görüyor | R21: 0.0166 | S21: 0.0877 | T21: 0 | U21: 0.8957 | V21: 0 | W21: 0 | X21: 0 | Y21: 0 | Z21: 0 | AA21: 1 | AC21: =IF(ISNUMBER(INDEX($A$2:$AA$25,20,MATCH('Mutlak Getiri'!$E$2,$A$1:$AA$1,0))),INDEX($A$2:$AA$25,20,MATCH('Mutlak Getiri'!$E$2,$A$1:$AA$1,0)),-1000000000)-ROW()/10000000 -> -0.043454896
A22: NSH | B22: Nurol Portföy İstatistiksel Arbitraj Hisse Senedi Serbest Fon (Hisse Senedi Yoğun Fon) | C22: Nurol Portföy | D22: 0.04 | E22: -0.19094002 | F22: 0.40784103 | G22: 2.2881274 | H22: 21.448497 | I22: 43.100585 | J22: 1288 | K22: 1283 | L22: -0.0038819876 | M22: 1.4906067e+09 | N22: 1.7980769e+09 | O22: 0.20627181 | P22: 0.14717034 | Q22: Görüyor | R22: 0 | S22: 0.2431 | T22: 0 | U22: 0.8609 | V22: 0 | W22: 0.0007 | X22: 0 | Y22: 0 | Z22: 0 | AA22: 1.1047 | AC22: =IF(ISNUMBER(INDEX($A$2:$AA$25,21,MATCH('Mutlak Getiri'!$E$2,$A$1:$AA$1,0))),INDEX($A$2:$AA$25,21,MATCH('Mutlak Getiri'!$E$2,$A$1:$AA$1,0)),-1000000000)-ROW()/10000000 -> -0.19094222
A23: HDA | B23: Hedef Portföy Dördüncü İstatistiksel Arbitraj Hisse Senedi Serbest (TL) Fon (Hisse Senedi Yoğun Fon) | C23: Hedef Portföy | D23: 0.035 | E23: -0.24379802 | F23: 0.18771924 | G23: 1.886673 | H23: 17.535776 | I23: 37.500812 | J23: 665 | K23: 594 | L23: -0.10676692 | M23: 3.4954044e+08 | N23: 1.3050923e+08 | O23: -0.62662623 | P23: 0.16502928 | Q23: Görüyor | R23: 0 | S23: -0.034 | T23: 0 | U23: 0.955 | V23: 0 | W23: 0.079 | X23: 0 | Y23: 0 | Z23: 0 | AA23: 1 | AC23: =IF(ISNUMBER(INDEX($A$2:$AA$25,22,MATCH('Mutlak Getiri'!$E$2,$A$1:$AA$1,0))),INDEX($A$2:$AA$25,22,MATCH('Mutlak Getiri'!$E$2,$A$1:$AA$1,0)),-1000000000)-ROW()/10000000 -> -0.24380032
A24: FS5 | B24: One Portföy Birinci İstatistiksel Arbitraj Hisse Senedi Serbest Fon (Hisse Senedi Yoğun Fon) | C24: One Portföy | D24: 0.035 | E24: -0.26980356 | F24: -2.3070321 | G24: -14.618383 | H24: -10.005207 | I24: 4.1603631 | J24: 11 | K24: 9 | L24: -0.18181818 | M24: 12432621 | N24: 19960236 | O24: 0.60547289 | P24: 1.634994 | Q24: Görüyor | R24: 0 | S24: 0.0344 | T24: 0 | U24: 0.602 | V24: 0 | W24: 0.3636 | X24: 0 | Y24: 0 | Z24: 0 | AA24: 1 | AC24: =IF(ISNUMBER(INDEX($A$2:$AA$25,23,MATCH('Mutlak Getiri'!$E$2,$A$1:$AA$1,0))),INDEX($A$2:$AA$25,23,MATCH('Mutlak Getiri'!$E$2,$A$1:$AA$1,0)),-1000000000)-ROW()/10000000 -> -0.26980596
A25: MGB | B25: İŞ Portföy Mutlak Getiri Hedefli Hisse Senedi Serbest Fon (Hisse Senedi Yoğun Fon) | C25: İŞ Portföy | D25: 0.032 | E25: -0.6391879 | F25: -1.5431967 | G25: -1.326148 | H25: 8.5681096 | I25: 28.867341 | J25: 548 | K25: 515 | L25: -0.060218978 | M25: 91408083 | N25: 69167685 | O25: -0.24330887 | P25: 0.50419896 | Q25: Görüyor | R25: 0 | S25: 0.1102 | T25: 0 | U25: 0.8898 | V25: 0 | W25: 0 | X25: 0 | Y25: 0 | Z25: 0 | AA25: 1 | AC25: =IF(ISNUMBER(INDEX($A$2:$AA$25,24,MATCH('Mutlak Getiri'!$E$2,$A$1:$AA$1,0))),INDEX($A$2:$AA$25,24,MATCH('Mutlak Getiri'!$E$2,$A$1:$AA$1,0)),-1000000000)-ROW()/10000000 -> -0.6391904

Sheet Mutlak Getiri
F1: 46216 | G1: 46210 | H1: 46185 | I1: 46022 | J1: 45852
B2: T-1: 14.07.2026 | D2: Sırala: | E2: Günlük%
B3: Fon Kodu | C3: Mutlak Getiri Fonları | D3: Yönetici | E3: FYÜ% | F3: Günlük% | G3: Haftalık | H3: Aylık | I3: Yılbaşına Göre | J3: Yıllık | K3: Yatırımcı Sayısı T-30 | L3: Yatırımcı Sayısı T-1 | M3: YS Değişim | N3: Önceki Ay FTD | O3: T-1 FTD | P3: FTD Değişim | Q3: Standart Sapma (Aylık) | R3: TEFAS Durumu | S3: Mevduat (TL) | T3: Vadeli İşlemler Nakit Teminatları | U3: Ters Repo Oranı | V3: Hisse Oranı | W3: Para Piyasaları Oranı | X3: Yatırım Fonları Katılma Payları | Y3: Özel Tahvil/Bono Oranı | Z3: Finansman Bonosu Oranı | AA3: Diğer Oran | AB3: Toplam
A4: 1 | B4: =INDEX('V_Mutlak Getiri'!A$2:A$25,MATCH(LARGE('V_Mutlak Getiri'!$AC$2:$AC$25,ROW()-3),'V_Mutlak Getiri'!$AC$2:$AC$25,0)) -> ZBO | C4: =INDEX('V_Mutlak Getiri'!B$2:B$25,MATCH(LARGE('V_Mutlak Getiri'!$AC$2:$AC$25,ROW()-3),'V_Mutlak Getiri'!$AC$2:$AC$25,0)) -> Ziraat Portföy Mutlak Getiri Hedefli Hisse Senedi Serbest Fon (Hisse Senedi Yoğun Fon) | D4: =INDEX('V_Mutlak Getiri'!C$2:C$25,MATCH(LARGE('V_Mutlak Getiri'!$AC$2:$AC$25,ROW()-3),'V_Mutlak Getiri'!$AC$2:$AC$25,0)) -> Ziraat Portföy | E4: =INDEX('V_Mutlak Getiri'!D$2:D$25,MATCH(LARGE('V_Mutlak Getiri'!$AC$2:$AC$25,ROW()-3),'V_Mutlak Getiri'!$AC$2:$AC$25,0)) -> 0.025 | F4: =INDEX('V_Mutlak Getiri'!E$2:E$25,MATCH(LARGE('V_Mutlak Getiri'!$AC$2:$AC$25,ROW()-3),'V_Mutlak Getiri'!$AC$2:$AC$25,0)) -> 1.9492138 | G4: =INDEX('V_Mutlak Getiri'!F$2:F$25,MATCH(LARGE('V_Mutlak Getiri'!$AC$2:$AC$25,ROW()-3),'V_Mutlak Getiri'!$AC$2:$AC$25,0)) -> 1.7721178 | H4: =INDEX('V_Mutlak Getiri'!G$2:G$25,MATCH(LARGE('V_Mutlak Getiri'!$AC$2:$AC$25,ROW()-3),'V_Mutlak Getiri'!$AC$2:$AC$25,0)) -> 1.7123685 | I4: =INDEX('V_Mutlak Getiri'!H$2:H$25,MATCH(LARGE('V_Mutlak Getiri'!$AC$2:$AC$25,ROW()-3),'V_Mutlak Getiri'!$AC$2:$AC$25,0)) -> 16.043799 | ... AB4: =INDEX('V_Mutlak Getiri'!AA$2:AA$25,MATCH(LARGE('V_Mutlak Getiri'!$AC$2:$AC$25,ROW()-3),'V_Mutlak Getiri'!$AC$2:$AC$25,0)) -> 1
A5: 2 | B5: =INDEX('V_Mutlak Getiri'!A$2:A$25,MATCH(LARGE('V_Mutlak Getiri'!$AC$2:$AC$25,ROW()-3),'V_Mutlak Getiri'!$AC$2:$AC$25,0)) -> MUT | C5: =INDEX('V_Mutlak Getiri'!B$2:B$25,MATCH(LARGE('V_Mutlak Getiri'!$AC$2:$AC$25,ROW()-3),'V_Mutlak Getiri'!$AC$2:$AC$25,0)) -> Garanti Portföy Mutlak Getiri Hedefli Hisse Senedi Serbest Fon (Hisse Senedi Yoğun Fon) | D5: =INDEX('V_Mutlak Getiri'!C$2:C$25,MATCH(LARGE('V_Mutlak Getiri'!$AC$2:$AC$25,ROW()-3),'V_Mutlak Getiri'!$AC$2:$AC$25,0)) -> Garanti Portföy | E5: =INDEX('V_Mutlak Getiri'!D$2:D$25,MATCH(LARGE('V_Mutlak Getiri'!$AC$2:$AC$25,ROW()-3),'V_Mutlak Getiri'!$AC$2:$AC$25,0)) -> 0.025 | F5: =INDEX('V_Mutlak Getiri'!E$2:E$25,MATCH(LARGE('V_Mutlak Getiri'!$AC$2:$AC$25,ROW()-3),'V_Mutlak Getiri'!$AC$2:$AC$25,0)) -> 1.481044 | G5: =INDEX('V_Mutlak Getiri'!F$2:F$25,MATCH(LARGE('V_Mutlak Getiri'!$AC$2:$AC$25,ROW()-3),'V_Mutlak Getiri'!$AC$2:$AC$25,0)) -> 1.7560271 | H5: =INDEX('V_Mutlak Getiri'!G$2:G$25,MATCH(LARGE('V_Mutlak Getiri'!$AC$2:$AC$25,ROW()-3),'V_Mutlak Getiri'!$AC$2:$AC$25,0)) -> 0.23858356 | I5: =INDEX('V_Mutlak Getiri'!H$2:H$25,MATCH(LARGE('V_Mutlak Getiri'!$AC$2:$AC$25,ROW()-3),'V_Mutlak Getiri'!$AC$2:$AC$25,0)) -> 11.529715 | ... AB5: =INDEX('V_Mutlak Getiri'!AA$2:AA$25,MATCH(LARGE('V_Mutlak Getiri'!$AC$2:$AC$25,ROW()-3),'V_Mutlak Getiri'!$AC$2:$AC$25,0)) -> 1
A6: 3 | B6: =INDEX('V_Mutlak Getiri'!A$2:A$25,MATCH(LARGE('V_Mutlak Getiri'!$AC$2:$AC$25,ROW()-3),'V_Mutlak Getiri'!$AC$2:$AC$25,0)) -> FYF | C6: =INDEX('V_Mutlak Getiri'!B$2:B$25,MATCH(LARGE('V_Mutlak Getiri'!$AC$2:$AC$25,ROW()-3),'V_Mutlak Getiri'!$AC$2:$AC$25,0)) -> Strateji Portföy Mutlak Getiri Hedefli Hisse Senedi Serbest Fon(hisse Senedi Yoğun) | D6: =INDEX('V_Mutlak Getiri'!C$2:C$25,MATCH(LARGE('V_Mutlak Getiri'!$AC$2:$AC$25,ROW()-3),'V_Mutlak Getiri'!$AC$2:$AC$25,0)) -> Strateji Portföy | E6: =INDEX('V_Mutlak Getiri'!D$2:D$25,MATCH(LARGE('V_Mutlak Getiri'!$AC$2:$AC$25,ROW()-3),'V_Mutlak Getiri'!$AC$2:$AC$25,0)) -> 0.025 | F6: =INDEX('V_Mutlak Getiri'!E$2:E$25,MATCH(LARGE('V_Mutlak Getiri'!$AC$2:$AC$25,ROW()-3),'V_Mutlak Getiri'!$AC$2:$AC$25,0)) -> 1.3986767 | G6: =INDEX('V_Mutlak Getiri'!F$2:F$25,MATCH(LARGE('V_Mutlak Getiri'!$AC$2:$AC$25,ROW()-3),'V_Mutlak Getiri'!$AC$2:$AC$25,0)) -> 1.2955648 | H6: =INDEX('V_Mutlak Getiri'!G$2:G$25,MATCH(LARGE('V_Mutlak Getiri'!$AC$2:$AC$25,ROW()-3),'V_Mutlak Getiri'!$AC$2:$AC$25,0)) -> 0.082116083 | I6: =INDEX('V_Mutlak Getiri'!H$2:H$25,MATCH(LARGE('V_Mutlak Getiri'!$AC$2:$AC$25,ROW()-3),'V_Mutlak Getiri'!$AC$2:$AC$25,0)) -> 8.8649762 | ... AB6: =INDEX('V_Mutlak Getiri'!AA$2:AA$25,MATCH(LARGE('V_Mutlak Getiri'!$AC$2:$AC$25,ROW()-3),'V_Mutlak Getiri'!$AC$2:$AC$25,0)) -> 1
A7: 4 | B7: =INDEX('V_Mutlak Getiri'!A$2:A$25,MATCH(LARGE('V_Mutlak Getiri'!$AC$2:$AC$25,ROW()-3),'V_Mutlak Getiri'!$AC$2:$AC$25,0)) -> MGH | C7: =INDEX('V_Mutlak Getiri'!B$2:B$25,MATCH(LARGE('V_Mutlak Getiri'!$AC$2:$AC$25,ROW()-3),'V_Mutlak Getiri'!$AC$2:$AC$25,0)) -> Teb Portföy Mutlak Getiri Hedefli Hisse Senedi Serbest Fon (Hisse Senedi Yoğun Fon) | D7: =INDEX('V_Mutlak Getiri'!C$2:C$25,MATCH(LARGE('V_Mutlak Getiri'!$AC$2:$AC$25,ROW()-3),'V_Mutlak Getiri'!$AC$2:$AC$25,0)) -> Teb Portföy | E7: =INDEX('V_Mutlak Getiri'!D$2:D$25,MATCH(LARGE('V_Mutlak Getiri'!$AC$2:$AC$25,ROW()-3),'V_Mutlak Getiri'!$AC$2:$AC$25,0)) -> 0.025 | F7: =INDEX('V_Mutlak Getiri'!E$2:E$25,MATCH(LARGE('V_Mutlak Getiri'!$AC$2:$AC$25,ROW()-3),'V_Mutlak Getiri'!$AC$2:$AC$25,0)) -> 0.41892707 | G7: =INDEX('V_Mutlak Getiri'!F$2:F$25,MATCH(LARGE('V_Mutlak Getiri'!$AC$2:$AC$25,ROW()-3),'V_Mutlak Getiri'!$AC$2:$AC$25,0)) -> 0.35725354 | H7: =INDEX('V_Mutlak Getiri'!G$2:G$25,MATCH(LARGE('V_Mutlak Getiri'!$AC$2:$AC$25,ROW()-3),'V_Mutlak Getiri'!$AC$2:$AC$25,0)) -> 0.84961332 | I7: =INDEX('V_Mutlak Getiri'!H$2:H$25,MATCH(LARGE('V_Mutlak Getiri'!$AC$2:$AC$25,ROW()-3),'V_Mutlak Getiri'!$AC$2:$AC$25,0)) -> 10.692413 | ... AB7: =INDEX('V_Mutlak Getiri'!AA$2:AA$25,MATCH(LARGE('V_Mutlak Getiri'!$AC$2:$AC$25,ROW()-3),'V_Mutlak Getiri'!$AC$2:$AC$25,0)) -> 1
A8: 5 | B8: =INDEX('V_Mutlak Getiri'!A$2:A$25,MATCH(LARGE('V_Mutlak Getiri'!$AC$2:$AC$25,ROW()-3),'V_Mutlak Getiri'!$AC$2:$AC$25,0)) -> HMG | C8: =INDEX('V_Mutlak Getiri'!B$2:B$25,MATCH(LARGE('V_Mutlak Getiri'!$AC$2:$AC$25,ROW()-3),'V_Mutlak Getiri'!$AC$2:$AC$25,0)) -> Hsbc Pyş Mutlak Getiri Hedefli Hisse Senedi Serbest (TL) Fon(hisse Senedi Yoğun Fon) | D8: =INDEX('V_Mutlak Getiri'!C$2:C$25,MATCH(LARGE('V_Mutlak Getiri'!$AC$2:$AC$25,ROW()-3),'V_Mutlak Getiri'!$AC$2:$AC$25,0)) -> Hsbc Portföy | E8: =INDEX('V_Mutlak Getiri'!D$2:D$25,MATCH(LARGE('V_Mutlak Getiri'!$AC$2:$AC$25,ROW()-3),'V_Mutlak Getiri'!$AC$2:$AC$25,0)) -> 0.025 | F8: =INDEX('V_Mutlak Getiri'!E$2:E$25,MATCH(LARGE('V_Mutlak Getiri'!$AC$2:$AC$25,ROW()-3),'V_Mutlak Getiri'!$AC$2:$AC$25,0)) -> 0.33762205 | G8: =INDEX('V_Mutlak Getiri'!F$2:F$25,MATCH(LARGE('V_Mutlak Getiri'!$AC$2:$AC$25,ROW()-3),'V_Mutlak Getiri'!$AC$2:$AC$25,0)) -> 0.75440579 | H8: =INDEX('V_Mutlak Getiri'!G$2:G$25,MATCH(LARGE('V_Mutlak Getiri'!$AC$2:$AC$25,ROW()-3),'V_Mutlak Getiri'!$AC$2:$AC$25,0)) -> 3.0375912 | I8: =INDEX('V_Mutlak Getiri'!H$2:H$25,MATCH(LARGE('V_Mutlak Getiri'!$AC$2:$AC$25,ROW()-3),'V_Mutlak Getiri'!$AC$2:$AC$25,0)) -> 13.91474 | ... AB8: =INDEX('V_Mutlak Getiri'!AA$2:AA$25,MATCH(LARGE('V_Mutlak Getiri'!$AC$2:$AC$25,ROW()-3),'V_Mutlak Getiri'!$AC$2:$AC$25,0)) -> 1
A9: 6 | B9: =INDEX('V_Mutlak Getiri'!A$2:A$25,MATCH(LARGE('V_Mutlak Getiri'!$AC$2:$AC$25,ROW()-3),'V_Mutlak Getiri'!$AC$2:$AC$25,0)) -> MTG | C9: =INDEX('V_Mutlak Getiri'!B$2:B$25,MATCH(LARGE('V_Mutlak Getiri'!$AC$2:$AC$25,ROW()-3),'V_Mutlak Getiri'!$AC$2:$AC$25,0)) -> Deniz Portföy Mutlak Getiri Hedefli Hisse Senedi Serbest Fon (Hisse Senedi Yogun Fon) | D9: =INDEX('V_Mutlak Getiri'!C$2:C$25,MATCH(LARGE('V_Mutlak Getiri'!$AC$2:$AC$25,ROW()-3),'V_Mutlak Getiri'!$AC$2:$AC$25,0)) -> Deniz Portföy | E9: =INDEX('V_Mutlak Getiri'!D$2:D$25,MATCH(LARGE('V_Mutlak Getiri'!$AC$2:$AC$25,ROW()-3),'V_Mutlak Getiri'!$AC$2:$AC$25,0)) -> 0.02 | F9: =INDEX('V_Mutlak Getiri'!E$2:E$25,MATCH(LARGE('V_Mutlak Getiri'!$AC$2:$AC$25,ROW()-3),'V_Mutlak Getiri'!$AC$2:$AC$25,0)) -> 0.32713565 | G9: =INDEX('V_Mutlak Getiri'!F$2:F$25,MATCH(LARGE('V_Mutlak Getiri'!$AC$2:$AC$25,ROW()-3),'V_Mutlak Getiri'!$AC$2:$AC$25,0)) -> 1.2618476 | H9: =INDEX('V_Mutlak Getiri'!G$2:G$25,MATCH(LARGE('V_Mutlak Getiri'!$AC$2:$AC$25,ROW()-3),'V_Mutlak Getiri'!$AC$2:$AC$25,0)) -> 3.5013027 | I9: =INDEX('V_Mutlak Getiri'!H$2:H$25,MATCH(LARGE('V_Mutlak Getiri'!$AC$2:$AC$25,ROW()-3),'V_Mutlak Getiri'!$AC$2:$AC$25,0)) -> 17.8574 | ... AB9: =INDEX('V_Mutlak Getiri'!AA$2:AA$25,MATCH(LARGE('V_Mutlak Getiri'!$AC$2:$AC$25,ROW()-3),'V_Mutlak Getiri'!$AC$2:$AC$25,0)) -> 1
